Workbook
Name _Toc82616607: '2 EstudiantadoEstProf'!#REF!

Sheet 2 EstudiantadoEstProf
A1: N.P. | B1: Clave Objetivo General | C1: Objetivo General | D1: Clave Objetivo Específico | E1: Objetivo Específico | F1: No. de meta en el PRDI | G1: Meta PRDI | H1: Clave de la meta | I1: Meta del espacio académico | J1: Actividad/Indicador | K1: Método de cálculo | L1: Nombre de las variables | M1: Valor de las variables | R1: Valor de los indicadores | W1: Medición (anual o acumulada) | X1: Área responsable | AN1: ESTATUS
M2: Ref. 2026 | N2: 2027 | O2: 2028 | P2: 2029 | Q2: 2030 | R2: Ref. 2026 | S2: 2027 | T2: 2028 | U2: 2029 | V2: 2030
A3: 1 | B3: PRDI25-29-Obj-36 | C3: Formar estudiantes de excelencia, a través de estudios profesionales pertinentes e inclusivos, con una vinculación permanente con estudiantes y personas egresadas, para su pleno desarrollo profesional y su contribución al bienestar social. | D3: PRDI2025-2029-Obj-58 | E3: Contar con planes de estudio pertinentes y de excelencia, en diferentes modalidades, que incorporen los criterios transversales del SEAES, de indicadores de instancias de evaluación externa y acreditación, y de organismos acreditadores, para formar profesionistas que contribuyan a la conformación de una sociedad más justa, libre, incluyente y pacífica, con una visión de sostenibilidad. | F3: 3 | G3: Incorporar contenidos temáticos o actividades académicas sobre los criterios transversales del seaes, en 30 planes de estudio reestructurados, durante la administración | H3: ACT-PRDI-NS-2726 | I3: meta fac | J3: Actividad | K3: Sin fórmula | L3: Incorporar contenidos temáticos o actividades académicas sobre los criterios transversales del seaes, en planes de estudio reestructurados | R3: =M3 -> 0 | S3: =N3 -> 0 | T3: =O3 -> 0 | U3: =P3 -> 0 | V3: =Q3 -> 0 | W3: Anual
A4: 2 | B4: PRDI25-29-Obj-36 | C4: Formar estudiantes de excelencia, a través de estudios profesionales pertinentes e inclusivos, con una vinculación permanente con estudiantes y personas egresadas, para su pleno desarrollo profesional y su contribución al bienestar social. | D4: PRDI2025-2029-Obj-58 | E4: Contar con planes de estudio pertinentes y de excelencia, en diferentes modalidades, que incorporen los criterios transversales del SEAES, de indicadores de instancias de evaluación externa y acreditación, y de organismos acreditadores, para formar profesionistas que contribuyan a la conformación de una sociedad más justa, libre, incluyente y pacífica, con una visión de sostenibilidad. | F4: 4 | G4: Contar con el acervo de 120 unidades de aprendizaje de estudios profesionales apegados a las referencias documentales básicas durante la administración | H4: ACT-PRDI-NS-2727 | J4: Actividad | K4: Sin fórmula | L4: Contar con el acervo de unidades de aprendizaje de estudios profesionales apegados a las referencias documentales básicas | R4: =M4 -> 0 | S4: =N4 -> 0 | T4: =O4 -> 0 | U4: =P4 -> 0 | V4: =Q4 -> 0 | W4: Anual
A5: 3 | B5: PRDI25-29-Obj-36 | C5: Formar estudiantes de excelencia, a través de estudios profesionales pertinentes e inclusivos, con una vinculación permanente con estudiantes y personas egresadas, para su pleno desarrollo profesional y su contribución al bienestar social. | D5: PRDI2025-2029-Obj-58 | E5: Contar con planes de estudio pertinentes y de excelencia, en diferentes modalidades, que incorporen los criterios transversales del SEAES, de indicadores de instancias de evaluación externa y acreditación, y de organismos acreditadores, para formar profesionistas que contribuyan a la conformación de una sociedad más justa, libre, incluyente y pacífica, con una visión de sostenibilidad. | F5: 7 | G5: Lograr que 89.13% de los programas educativos de estudios profesionales evaluables cuenten con reconocimiento por su excelencia, para 2029 | H5: IND-NS-210 | J5: Indicador | K5: (Número de programas educativos de estudios profesionales con reconocimiento por su excelencia / Número de programas educativos de Estudios Profesionales evaluables)*100 | L5: Número de programas educativos de estudios profesionales con reconocimiento por su excelencia | R5: =IF(M6,M5/M6*100,"0") -> 0 | S5: =IF(N6,N5/N6*100,"0") -> 0 | T5: =IF(O6,O5/O6*100,"0") -> 0 | U5: =IF(P6,P5/P6*100,"0") -> 0 | V5: =IF(Q6,Q5/Q6*100,"0") -> 0 | W5: Anual
L6: Número de programas educativos de Estudios Profesionales evaluables
A7: 4 | B7: PRDI25-29-Obj-36 | C7: Formar estudiantes de excelencia, a través de estudios profesionales pertinentes e inclusivos, con una vinculación permanente con estudiantes y personas egresadas, para su pleno desarrollo profesional y su contribución al bienestar social. | D7: PRDI2025-2029-Obj-58 | E7: Contar con planes de estudio pertinentes y de excelencia, en diferentes modalidades, que incorporen los criterios transversales del SEAES, de indicadores de instancias de evaluación externa y acreditación, y de organismos acreditadores, para formar profesionistas que contribuyan a la conformación de una sociedad más justa, libre, incluyente y pacífica, con una visión de sostenibilidad. | F7: 8 | G7: Lograr que 92.9% de la matrícula en programas educativos de estudios profesionales evaluables, curse en programas educativos reconocidos por su excelencia, para 2029 | H7: IND-PRDI-351 | J7: Indicador | K7: (Matrícula de estudiantes de estudios profesionales del sistema dependiente en programas educativos reconocidos por su excelencia / Matrícula de estudiantes de estudios profesionales del sistema dependiente en programas educativos evaluables)*100 | L7: Matrícula de estudiantes de estudios profesionales del sistema dependiente en programas educativos reconocidos por su excelencia | R7: =IF(M8,M7/M8*100,"0") -> 0 | S7: =IF(N8,N7/N8*100,"0") -> 0 | T7: =IF(O8,O7/O8*100,"0") -> 0 | U7: =IF(P8,P7/P8*100,"0") -> 0 | V7: =IF(Q8,Q7/Q8*100,"0") -> 0 | W7: Anual
L8: Matrícula de estudiantes de estudios profesionales del sistema dependiente en programas educativos evaluables
A9: 5 | B9: PRDI25-29-Obj-36 | C9: Formar estudiantes de excelencia, a través de estudios profesionales pertinentes e inclusivos, con una vinculación permanente con estudiantes y personas egresadas, para su pleno desarrollo profesional y su contribución al bienestar social. | D9: PRDI25-29-Obj-81 | E9: Fortalecer la formación disciplinar e integral del estudiantado y su educación continua, en congruencia con el modelo educativo institucional, para fomentar su desarrollo humano completo y maximizar su potencial académico y profesional, así como su retribución social, en los diferentes sectores. | F9: 9 | G9: Lograr que 72% de los sustentantes que presentan el EGEL obtengan testimonios de desempeño sobresaliente o satisfactorio, para 2029 | H9: IND-PRDI-200 | J9: Indicador | K9: (Número de sustentantes de estudios profesionales que obtienen testimonio de desempeño sobresaliente o satisfactorio en el EGEL / Total de sustentantes de estudios profesionales que presentan los EGEL)*100 | L9: Número de sustentantes de estudios profesionales que obtienen testimonio de desempeño sobresaliente o satisfactorio en el EGEL | R9: =IF(M10,M9/M10*100,"0") -> 0 | S9: =IF(N10,N9/N10*100,"0") -> 0 | T9: =IF(O10,O9/O10*100,"0") -> 0 | U9: =IF(P10,P9/P10*100,"0") -> 0 | V9: =IF(Q10,Q9/Q10*100,"0") -> 0 | W9: Anual
L10: Total de sustentantes de estudios profesionales que presentan los EGEL
A11: 6 | B11: PRDI25-29-Obj-36 | C11: Formar estudiantes de excelencia, a través de estudios profesionales pertinentes e inclusivos, con una vinculación permanente con estudiantes y personas egresadas, para su pleno desarrollo profesional y su contribución al bienestar social. | D11: PRDI25-29-Obj-81 | E11: Fortalecer la formación disciplinar e integral del estudiantado y su educación continua, en congruencia con el modelo educativo institucional, para fomentar su desarrollo humano completo y maximizar su potencial académico y profesional, así como su retribución social, en los diferentes sectores. | F11: 10 | G11: Implementar 1 programa de preparación para EGEL anualmente | H11: ACT-PRDI-NS-2781 | J11: Actividad | K11: Sin fórmula | L11: Implementar un programa de preparación para EGEL | M11: 0 | N11: 0 | P11: 0 | Q11: 0 | R11: =M11 -> 0 | S11: =N11 -> 0 | T11: =O11 -> 0 | U11: =P11 -> 0 | V11: =Q11 -> 0 | W11: Anual
A12: 7 | B12: PRDI25-29-Obj-36 | C12: Formar estudiantes de excelencia, a través de estudios profesionales pertinentes e inclusivos, con una vinculación permanente con estudiantes y personas egresadas, para su pleno desarrollo profesional y su contribución al bienestar social. | D12: PRDI25-29-Obj-81 | E12: Fortalecer la formación disciplinar e integral del estudiantado y su educación continua, en congruencia con el modelo educativo institucional, para fomentar su desarrollo humano completo y maximizar su potencial académico y profesional, así como su retribución social, en los diferentes sectores. | F12: 14 | G12: Lograr que 550 estudiantes de estudios profesionales participen en movilidad intrainstitucional durante la administración | H12: ACT-PRDI-NS-2785 | J12: Actividad | K12: Sin fórmula | L12: Lograr que estudiantes de estudios profesionales participen en movilidad intrainstitucional | R12: =M12 -> 0 | S12: =N12 -> 0 | T12: =O12 -> 0 | U12: =P12 -> 0 | V12: =Q12 -> 0 | W12: Anual
A13: 8 | B13: PRDI25-29-Obj-36 | C13: Formar estudiantes de excelencia, a través de estudios profesionales pertinentes e inclusivos, con una vinculación permanente con estudiantes y personas egresadas, para su pleno desarrollo profesional y su contribución al bienestar social. | D13: PRDI25-29-Obj-81 | E13: Fortalecer la formación disciplinar e integral del estudiantado y su educación continua, en congruencia con el modelo educativo institucional, para fomentar su desarrollo humano completo y maximizar su potencial académico y profesional, así como su retribución social, en los diferentes sectores. | F13: 15 | G13: Lograr anualmente que 100% de los estudiantes de estudios profesionales estén beneficiados con el nuevo Programa Institucional de Tutoría Académica | H13: IND-PRDI-353 | J13: Indicador | K13: (Número de estudiantes de estudios profesionales beneficiados con tutoría/ Total de estudiantes de estudios profesionales) * 100 | L13: Número de estudiantes de estudios profesionales beneficiados con tutoría | R13: =IF(M14,M13/M14*100,"0") -> 0 | S13: =IF(N14,N13/N14*100,"0") -> 0 | T13: =IF(O14,O13/O14*100,"0") -> 0 | U13: =IF(P14,P13/P14*100,"0") -> 0 | V13: =IF(Q14,Q13/Q14*100,"0") -> 0 | W13: Anual
L14: Total de estudiantes de estudios profesionales
A15: 9 | B15: PRDI25-29-Obj-36 | C15: Formar estudiantes de excelencia, a través de estudios profesionales pertinentes e inclusivos, con una vinculación permanente con estudiantes y personas egresadas, para su pleno desarrollo profesional y su contribución al bienestar social. | D15: PRDI25-29-Obj-81 | E15: Fortalecer la formación disciplinar e integral del estudiantado y su educación continua, en congruencia con el modelo educativo institucional, para fomentar su desarrollo humano completo y maximizar su potencial académico y profesional, así como su retribución social, en los diferentes sectores. | F15: 17 | G15: Lograr que 1 030 estudiantes de estudios profesionales participen en movilidad nacional e internacional durante la administración | H15: ACT-PRDI-NS-2789 | J15: Actividad | K15: Sin fórmula | L15: Lograr que estudiantes de estudios profesionales participen en movilidad nacional e internacional | R15: =M15 -> 0 | S15: =N15 -> 0 | T15: =O15 -> 0 | U15: =P15 -> 0 | V15: =Q15 -> 0 | W15: Anual
A16: 10 | B16: PRDI25-29-Obj-36 | C16: Formar estudiantes de excelencia, a través de estudios profesionales pertinentes e inclusivos, con una vinculación permanente con estudiantes y personas egresadas, para su pleno desarrollo profesional y su contribución al bienestar social. | D16: PRDI25-29-Obj-81 | E16: Fortalecer la formación disciplinar e integral del estudiantado y su educación continua, en congruencia con el modelo educativo institucional, para fomentar su desarrollo humano completo y maximizar su potencial académico y profesional, así como su retribución social, en los diferentes sectores. | F16: 19 | G16: Realizar anualmente en los 55 espacios académicos un proyecto colaborativo de beneficio social | H16: ACT-PRDI-NS-2729 | J16: Actividad | K16: Sin fórmula | L16: Realizar en los espacios académicos un proyecto colaborativo de beneficio social | R16: =M16 -> 0 | S16: =N16 -> 0 | T16: =O16 -> 0 | U16: =P16 -> 0 | V16: =Q16 -> 0 | W16: Anual
A17: 11 | B17: PRDI25-29-Obj-36 | C17: Formar estudiantes de excelencia, a través de estudios profesionales pertinentes e inclusivos, con una vinculación permanente con estudiantes y personas egresadas, para su pleno desarrollo profesional y su contribución al bienestar social. | D17: PRDI25-29-Obj-81 | E17: Fortalecer la formación disciplinar e integral del estudiantado y su educación continua, en congruencia con el modelo educativo institucional, para fomentar su desarrollo humano completo y maximizar su potencial académico y profesional, así como su retribución social, en los diferentes sectores. | F17: 21 | G17: Contar con 70 manuales de prácticas apegados a los indicadores del Sistema para Evaluar la Calidad de Medios Educativos anualmente | H17: ACT-PRDI-NS-2792 | J17: Actividad | K17: Sin fórmula | L17: Contar con manuales de prácticas apegados a los indicadores del Sistema para Evaluar la Calidad de Medios Educativos | R17: =M17 -> 0 | S17: =N17 -> 0 | T17: =O17 -> 0 | U17: =P17 -> 0 | V17: =Q17 -> 0 | W17: Anual
A18: 12 | B18: PRDI25-29-Obj-36 | C18: Formar estudiantes de excelencia, a través de estudios profesionales pertinentes e inclusivos, con una vinculación permanente con estudiantes y personas egresadas, para su pleno desarrollo profesional y su contribución al bienestar social. | D18: PRDI25-29-Obj-81 | E18: Fortalecer la formación disciplinar e integral del estudiantado y su educación continua, en congruencia con el modelo educativo institucional, para fomentar su desarrollo humano completo y maximizar su potencial académico y profesional, así como su retribución social, en los diferentes sectores. | F18: 29 | G18: Lograr que 80.03% de las GEI disponibles en SEDUCA sean utilizadas, para 2029 | H18: IND-PRDI-357 | J18: Indicador | K18: (Número de guías de estudio independiente utilizadas / Número total de guías de estudio independiente vigentes disponibles en SEDUCA) *100 | L18: Número de guías de estudio independiente utilizadas | R18: =IF(M19,M18/M19*100,"0") -> 0 | S18: =IF(N19,N18/N19*100,"0") -> 0 | T18: =IF(O19,O18/O19*100,"0") -> 0 | U18: =IF(P19,P18/P19*100,"0") -> 0 | V18: =IF(Q19,Q18/Q19*100,"0") -> 0 | W18: Anual
L19: Número total de guías de estudio independiente vigentes disponibles en SEDUCA
A20: 13 | B20: PRDI25-29-Obj-36 | C20: Formar estudiantes de excelencia, a través de estudios profesionales pertinentes e inclusivos, con una vinculación permanente con estudiantes y personas egresadas, para su pleno desarrollo profesional y su contribución al bienestar social. | D20: PRDI25-29-Obj-81 | E20: Fortalecer la formación disciplinar e integral del estudiantado y su educación continua, en congruencia con el modelo educativo institucional, para fomentar su desarrollo humano completo y maximizar su potencial académico y profesional, así como su retribución social, en los diferentes sectores. | F20: 30 | G20: Incrementar a 52 000 el número de estudiantes de estudios profesionales en la renovada plataforma seduca, para 2029 | H20: ACT-PRDI-NS-2728 | J20: Actividad | K20: Sin fórmula | L20: Incrementar el número de estudiantes de estudios profesionales en la renovada plataforma seduca | R20: =M20 -> 0 | S20: =N20 -> 0 | T20: =O20 -> 0 | U20: =P20 -> 0 | V20: =Q20 -> 0 | W20: Anual
A21: 14 | B21: PRDI25-29-Obj-36 | C21: Formar estudiantes de excelencia, a través de estudios profesionales pertinentes e inclusivos, con una vinculación permanente con estudiantes y personas egresadas, para su pleno desarrollo profesional y su contribución al bienestar social. | D21: PRDI25-29-Obj-81 | E21: Fortalecer la formación disciplinar e integral del estudiantado y su educación continua, en congruencia con el modelo educativo institucional, para fomentar su desarrollo humano completo y maximizar su potencial académico y profesional, así como su retribución social, en los diferentes sectores. | F21: 33 | G21: Desarrollar 470 actividades académicas de educación continua al año | H21: ACT-PRDI-NS-2805 | J21: Actividad | K21: Sin fórmula | L21: Desarrollar actividades académicas de educación continua | R21: =M21 -> 0 | S21: =N21 -> 0 | T21: =O21 -> 0 | U21: =P21 -> 0 | V21: =Q21 -> 0 | W21: Anual
A22: 16 | B22: PRDI25-29-Obj-36 | C22: Formar estudiantes de excelencia, a través de estudios profesionales pertinentes e inclusivos, con una vinculación permanente con estudiantes y personas egresadas, para su pleno desarrollo profesional y su contribución al bienestar social. | D22: PRDI25-29-Obj-81 | E22: Fortalecer la formación disciplinar e integral del estudiantado y su educación continua, en congruencia con el modelo educativo institucional, para fomentar su desarrollo humano completo y maximizar su potencial académico y profesional, así como su retribución social, en los diferentes sectores. | F22: 37 | G22: Certificar en una segunda lengua a 720 estudiantes de estudios profesionales anualmente | H22: ACT-PRDI-NS-2205 | J22: Actividad | K22: Sin fórmula | L22: Certificar internacionalmente en una segunda lengua a estudiantes de estudios profesionales | R22: =M22 -> 0 | S22: =N22 -> 0 | T22: =O22 -> 0 | U22: =P22 -> 0 | V22: =Q22 -> 0 | W22: Anual
A23: 17 | B23: PRDI25-29-Obj-36 | C23: Formar estudiantes de excelencia, a través de estudios profesionales pertinentes e inclusivos, con una vinculación permanente con estudiantes y personas egresadas, para su pleno desarrollo profesional y su contribución al bienestar social. | D23: PRDI25-29-Obj-82 | E23: Contribuir al acceso, permanencia y egreso del alumnado de estudios profesionales para su formación integral y la conclusión de sus estudios profesionales. | F23: 42 | G23: Incrementar la matrícula a 78 002 estudiantes de estudios profesionales en sus diversas modalidades para 2029 | H23: ACT-PRDI-NS-1764 | J23: Actividad | K23: Sin fórmula | L23: Atender la matrícula de Estudios Profesionales en sus diversas modalidades | M23: =M14 -> 0 | N23: =N14 -> 0 | O23: =O14 -> 0 | P23: =P14 -> 0 | Q23: =Q14 -> 0 | R23: =M23 -> 0 | S23: =N23 -> 0 | T23: =O23 -> 0 | U23: =P23 -> 0 | V23: =Q23 -> 0 | W23: Anual
A24: 18 | B24: PRDI25-29-Obj-36 | C24: Formar estudiantes de excelencia, a través de estudios profesionales pertinentes e inclusivos, con una vinculación permanente con estudiantes y personas egresadas, para su pleno desarrollo profesional y su contribución al bienestar social. | D24: PRDI25-29-Obj-82 | E24: Contribuir al acceso, permanencia y egreso del alumnado de estudios profesionales para su formación integral y la conclusión de sus estudios profesionales. | F24: 43 | G24: Contar con una titulación por cohorte a 2029 de 30.5% | H24: IND-PRDI-40 | J24: Indicador | K24: (Titulados al primer año de egreso/Nuevo ingreso n-5 )*100 | L24: Titulados al primer año de egreso | R24: =IF(M25,M24/M25*100,"0") -> 0 | S24: =IF(N25,N24/N25*100,"0") -> 0 | T24: =IF(O25,O24/O25*100,"0") -> 0 | U24: =IF(P25,P24/P25*100,"0") -> 0 | V24: =IF(Q25,Q24/Q25*100,"0") -> 0 | W24: Anual
L25: Nuevo ingreso n-5
A26: 19 | B26: PRDI25-29-Obj-36 | C26: Formar estudiantes de excelencia, a través de estudios profesionales pertinentes e inclusivos, con una vinculación permanente con estudiantes y personas egresadas, para su pleno desarrollo profesional y su contribución al bienestar social. | D26: PRDI25-29-Obj-82 | E26: Contribuir al acceso, permanencia y egreso del alumnado de estudios profesionales para su formación integral y la conclusión de sus estudios profesionales. | F26: 44 | G26: Implementar semestralmente 1 programa de fomento a la titulación | H26: ACT-PRDI-NS-2814 | J26: Actividad | K26: Sin fórmula | L26: Implementar un programa de fomento a la titulación | R26: =M26 -> 0 | S26: =N26 -> 0 | T26: =O26 -> 0 | U26: =P26 -> 0 | V26: =Q26 -> 0 | W26: Anual
A27: 20 | B27: PRDI25-29-Obj-36 | C27: Formar estudiantes de excelencia, a través de estudios profesionales pertinentes e inclusivos, con una vinculación permanente con estudiantes y personas egresadas, para su pleno desarrollo profesional y su contribución al bienestar social. | D27: PRDI25-29-Obj-82 | E27: Contribuir al acceso, permanencia y egreso del alumnado de estudios profesionales para su formación integral y la conclusión de sus estudios profesionales. | F27: 45 | G27: Lograr la eficiencia terminal por cohorte en estudios Profesionales de 53.59% en 2029 | H27: IND-NS-127 | J27: Indicador | K27: (La suma acumulada del número de egresados de la cohorte de estudios profesionales en cada uno de los años que dura la cohorte/Número total de alumnos de ingreso a primer año de la cohorte)*100 | L27: La suma acumulada del número de egresados de la cohorte de estudios profesionales en cada uno de los años que dura la cohorte | R27: =IF(M28,M27/M28*100,"0") -> 0 | S27: =IF(N28,N27/N28*100,"0") -> 0 | T27: =IF(O28,O27/O28*100,"0") -> 0 | U27: =IF(P28,P27/P28*100,"0") -> 0 | V27: =IF(Q28,Q27/Q28*100,"0") -> 0 | W27: Anual
L28: Número total de alumnos de ingreso a primer año de la cohorte
A29: 21 | B29: PRDI25-29-Obj-36 | C29: Formar estudiantes de excelencia, a través de estudios profesionales pertinentes e inclusivos, con una vinculación permanente con estudiantes y personas egresadas, para su pleno desarrollo profesional y su contribución al bienestar social. | D29: PRDI25-29-Obj-82 | E29: Contribuir al acceso, permanencia y egreso del alumnado de estudios profesionales para su formación integral y la conclusión de sus estudios profesionales. | F29: 46 | G29: Disminuir a 7.80% el abandono escolar de estudios profesionales al término de la administración | H29: IND-PRDI-34 | J29: Indicador | K29: (1-((Matrícula total n mas 1-Nuevo ingreso 1o n mas 1+Egresados n)/(Matrícula total n)))*100 | L29: Matrícula total n mas 1 | M29: =M14 -> 0 | N29: =N14 -> 0 | O29: =O14 -> 0 | P29: =P14 -> 0 | R29: =IF(M32,(1-((M29-M30+M31)/(M32)))*100,"0") -> 0 | S29: =IF(N32,(1-((N29-N30+N31)/(N32)))*100,"0") -> 0 | T29: =IF(O32,(1-((O29-O30+O31)/(O32)))*100,"0") -> 0 | U29: =IF(P32,(1-((P29-P30+P31)/(P32)))*100,"0") -> 0 | V29: =IF(Q32,(1-((Q29-Q30+Q31)/(Q32)))*100,"0") -> 0 | W29: Anual
L30: Nuevo ingreso 1o n mas 1
L31: Egresados n
L32: Matrícula total n | N32: =M29 -> 0 | O32: =N29 -> 0 | P32: =O29 -> 0
A33: 22 | B33: PRDI25-29-Obj-36 | C33: Formar estudiantes de excelencia, a través de estudios profesionales pertinentes e inclusivos, con una vinculación permanente con estudiantes y personas egresadas, para su pleno desarrollo profesional y su contribución al bienestar social. | D33: PRDI25-29-Obj-82 | E33: Contribuir al acceso, permanencia y egreso del alumnado de estudios profesionales para su formación integral y la conclusión de sus estudios profesionales. | F33: 53 | G33: Otorgar anualmente 38 000 becas, apoyos o estímulos institucionales a estudiantes de Estudios Profesionales | H33: ACT-PRDI-NS-2297 | J33: Actividad | K33: Sin fórmula | L33: Otorgar becas, apoyos o estímulos a alumnos de estudios profesionales para la permanencia y conclusión de estudios | R33: =M33 -> 0 | S33: =N33 -> 0 | T33: =O33 -> 0 | U33: =P33 -> 0 | V33: =Q33 -> 0 | W33: Anual
A34: 23 | B34: PRDI25-29-Obj-36 | C34: Formar estudiantes de excelencia, a través de estudios profesionales pertinentes e inclusivos, con una vinculación permanente con estudiantes y personas egresadas, para su pleno desarrollo profesional y su contribución al bienestar social. | D34: PRDI25-29-Obj-82 | E34: Contribuir al acceso, permanencia y egreso del alumnado de estudios profesionales para su formación integral y la conclusión de sus estudios profesionales. | F34: 55 | G34: Lograr que 98% del total de estudiantes activos de Estudios Profesionales cuenten con servicios de salud a 2029 | H34: IND-PRDI-366 | J34: Indicador | K34: (Alumnos afiliados al Seguro Facultativo de Estudios Profesionales / Matrícula activa de Estudios Profesionales)*100 | L34: Alumnos afiliados al Seguro Facultativo de Estudios Profesionales | R34: =IF(M35,M34/M35*100,"0") -> 0 | S34: =IF(N35,N34/N35*100,"0") -> 0 | T34: =IF(O35,O34/O35*100,"0") -> 0 | U34: =IF(P35,P34/P35*100,"0") -> 0 | V34: =IF(Q35,Q34/Q35*100,"0") -> 0 | W34: Anual
L35: Matrícula activa de Estudios Profesionales | M35: =M14 -> 0 | N35: =N14 -> 0 | O35: =O14 -> 0 | P35: =P14 -> 0 | Q35: =Q14 -> 0
A36: 24 | B36: PRDI25-29-Obj-36 | C36: Formar estudiantes de excelencia, a través de estudios profesionales pertinentes e inclusivos, con una vinculación permanente con estudiantes y personas egresadas, para su pleno desarrollo profesional y su contribución al bienestar social. | D36: PRDI25-29-Obj-82 | E36: Contribuir al acceso, permanencia y egreso del alumnado de estudios profesionales para su formación integral y la conclusión de sus estudios profesionales. | F36: 57 | G36: Lograr la participación de 32 300 estudiantes y personas egresadas en los sectores gubernamental, productivo y social, mediante las prácticas o estancias profesionales, al cierre de la administración | H36: ACT-PRDI-NS-2285 | J36: Actividad | K36: Sin fórmula | L36: Lograr la participación de alumnos en los sectores gubernamental, productivo y social mediante las prácticas o estancias profesionales | R36: =M36 -> 0 | S36: =N36 -> 0 | T36: =O36 -> 0 | U36: =P36 -> 0 | V36: =Q36 -> 0 | W36: Anual
A37: 25 | B37: PRDI25-29-Obj-36 | C37: Formar estudiantes de excelencia, a través de estudios profesionales pertinentes e inclusivos, con una vinculación permanente con estudiantes y personas egresadas, para su pleno desarrollo profesional y su contribución al bienestar social. | D37: PRDI25-29-Obj-82 | E37: Contribuir al acceso, permanencia y egreso del alumnado de estudios profesionales para su formación integral y la conclusión de sus estudios profesionales. | F37: 58 | G37: Lograr la participación de 500 estudiantes de estudios profesionales en cursos, talleres o actividades de capacitación de empleabilidad, realizadas en conjunto con instituciones externas, anualmente | H37: ACT-PRDI-NS-2826 | J37: Actividad | K37: Sin fórmula | L37: Lograr la participación de estudiantes de estudios profesionales en cursos, talleres o actividades de capacitación de empleabilidad, realizadas en conjunto con instituciones externas | R37: =M37 -> 0 | S37: =N37 -> 0 | T37: =O37 -> 0 | U37: =P37 -> 0 | V37: =Q37 -> 0 | W37: Anual
A38: 26 | B38: PRDI25-29-Obj-36 | C38: Formar estudiantes de excelencia, a través de estudios profesionales pertinentes e inclusivos, con una vinculación permanente con estudiantes y personas egresadas, para su pleno desarrollo profesional y su contribución al bienestar social. | D38: PRDI25-29-Obj-82 | E38: Contribuir al acceso, permanencia y egreso del alumnado de estudios profesionales para su formación integral y la conclusión de sus estudios profesionales. | F38: 61 | G38: Realizar 10 eventos de promoción y difusión en apoyo al desarrollo profesional para el empleo y la inserción laboral, durante la administración | H38: ACT-PRDI-NS-2825 | J38: Actividad | K38: Sin fórmula | L38: Realizar eventos de promoción y difusión en apoyo al desarrollo profesional para el empleo y la inserción laboral | R38: =M38 -> 0 | S38: =N38 -> 0 | T38: =O38 -> 0 | U38: =P38 -> 0 | V38: =Q38 -> 0 | W38: Anual
A39: 27 | B39: PRDI25-29-Obj-36 | C39: Formar estudiantes de excelencia, a través de estudios profesionales pertinentes e inclusivos, con una vinculación permanente con estudiantes y personas egresadas, para su pleno desarrollo profesional y su contribución al bienestar social. | D39: PRDI25-29-Obj-83 | E39: Fortalecer la vinculación, acompañamiento y seguimiento de egresados de estudios profesionales, para favorecer las prácticas profesionales, empleabilidad y colaboración con el sector productivo, con un sentido de identidad. | F39: 64 | G39: Realizar 40 intervenciones de impacto anuales en espacios académicos para fortalecer la vinculación colaborativa entre egresados y estudiantes | H39: ACT-PRDI-NS-2753 | J39: Actividad | K39: Sin fórmula | L39: Realizar intervenciones de impacto en espacios académicos para fortalecer la vinculación colaborativa entre egresados y estudiantes | R39: =M39 -> 0 | S39: =N39 -> 0 | T39: =O39 -> 0 | U39: =P39 -> 0 | V39: =Q39 -> 0 | W39: Anual

Sheet Hoja1
A1: Proyecto | B1: Actividades | C1: Indicadores | D1: Total
A2: 2 EstudiantadoEstProf | B2: 18 | C2: 9 | D2: =B2+C2 -> 27
A3: 3 Est avanzados excelencia | B3: 6 | C3: 1 | D3: =B3+C3 -> 7
A4: 4 Investigación abierta | B4: 3 | C4: 5 | D4: =B4+C4 -> 8
A5: 5 Innovación, desarrollo tec | B5: 2 | C5: 0 | D5: =B5+C5 -> 2
A6: 6 Dif y divulga de la ciencia | B6: 4 | C6: 0 | D6: =B6+C6 -> 4
A7: 7 Cultura desarrollo integral | B7: 6 | C7: 0 | D7: =B7+C7 -> 6
A8: 8 Deporte universitario | B8: 2 | C8: 3 | D8: =B8+C8 -> 5
A9: 9 Fortalecimiento docente | B9: 4 | C9: 6 | D9: =B9+C9 -> 10
A10: 10 Dignificación las y los trab | B10: 0 | C10: 3 | D10: =B10+C10 -> 3
A11: 11 Gestión administrativa | B11: 2 | C11: 0 | D11: =B11+C11 -> 2
A12: 12 Fortalecimiento tecnológico | B12: 2 | C12: 0 | D12: =B12+C12 -> 2
A13: 13 Gobernanza | B13: 8 | C13: 0 | D13: =B13+C13 -> 8
... A19: 22 Sostenibilidad ambiental | B19: 12 | C19: 0 | D19: =B19+C19 -> 12
B20: =SUM(B2:B19) -> 91 | C20: =SUM(C2:C19) -> 32 | D20: =SUM(D2:D19) -> 123

Sheet 3 Est avanzados excelencia
A1: N.P. | B1: Clave Objetivo General | C1: Objetivo General | D1: Clave Objetivo Específico | E1: Objetivo Específico | F1: No. de meta en el PRDI | G1: Meta PRDI | H1: Clave de la meta | I1: Meta del espacio académico | J1: Actividad/Indicador | K1: Método de cálculo | L1: Nombre de las variables | M1: Valor de las variables | R1: Valor de los indicadores | W1: Medición (anual o acumulada) | X1: Área responsable
M2: Ref. 2026 | N2: 2027 | O2: 2028 | P2: 2029 | Q2: 2030 | R2: Ref. 2026 | S2: 2027 | T2: 2028 | U2: 2029 | V2: 2030
A3: 1 | B3: PRDI25-29-Obj-37 | C3: Garantizar una formación en estudios avanzados de excelencia y pertinencia social, a través del desarrollo de programas innovadores con la integración de la investigación de la Agenda Estratégica de Investigación, para asegurar que el conocimiento generado impulse la transformación social. | D3: PRDI2025-2029-Obj-59 | E3: Incrementar la matrícula de estudios avanzados con enfoque de equidad e inclusión regional para diversificar el acceso a la formación de alto nivel. | F3: 6 | G3: Contar con 233 estudiantes de estudios avanzados participantes en estancias cortas o movilidad académica, a 2029 | H3: ACT-PRDI-NS-2838 | J3: Actividad | K3: Sin fórmula | L3: Contar con estudiantes de estudios avanzados participantes en estancias cortas o movilidad académica | R3: =M3 -> 0 | S3: =N3 -> 0 | T3: =O3 -> 0 | U3: =P3 -> 0 | V3: =Q3 -> 0 | W3: Anual
A4: 2 | B4: PRDI25-29-Obj-37 | C4: Garantizar una formación en estudios avanzados de excelencia y pertinencia social, a través del desarrollo de programas innovadores con la integración de la investigación de la Agenda Estratégica de Investigación, para asegurar que el conocimiento generado impulse la transformación social. | D4: PRDI2025-2029-Obj-59 | E4: Incrementar la matrícula de estudios avanzados con enfoque de equidad e inclusión regional para diversificar el acceso a la formación de alto nivel. | F4: 16 | G4: Contar 4 350 alumnos en estudios avanzados, a 2029 | H4: ACT-PRDI-NS-2685 | J4: Actividad | K4: Sin fórmula | L4: Atender la matrícula de estudios avanzados para la generación y aplicación del conocimiento | R4: =M4 -> 0 | S4: =N4 -> 0 | T4: =O4 -> 0 | U4: =P4 -> 0 | V4: =Q4 -> 0 | W4: Anual
A5: 3 | B5: PRDI25-29-Obj-37 | C5: Garantizar una formación en estudios avanzados de excelencia y pertinencia social, a través del desarrollo de programas innovadores con la integración de la investigación de la Agenda Estratégica de Investigación, para asegurar que el conocimiento generado impulse la transformación social. | D5: PRDI25-29-Obj-84 | E5: Consolidar una oferta educativa de estudios avanzados de excelencia, para garantizar la inclusión, la pertinencia social y la alineación con las demandas de los sectores productivo, gubernamental y social. | F5: 12 | G5: Ofertar 1 nuevo programa de estudios avanzados o diplomado superior en los CU y UAP vinculado con entidades de gobierno o industria, anualmente | H5: ACT-PRDI-NS-2844 | J5: Actividad | K5: Sin fórmula | L5: Ofertar nuevos programas de estudios avanzados o diplomado superior en los CU y UAP vinculado con entidades de gobierno o industria | R5: =M5 -> 0 | S5: =N5 -> 0 | T5: =O5 -> 0 | U5: =P5 -> 0 | V5: =Q5 -> 0 | W5: Anual
A6: 4 | B6: PRDI25-29-Obj-37 | C6: Garantizar una formación en estudios avanzados de excelencia y pertinencia social, a través del desarrollo de programas innovadores con la integración de la investigación de la Agenda Estratégica de Investigación, para asegurar que el conocimiento generado impulse la transformación social. | D6: PRDI25-29-Obj-84 | E6: Consolidar una oferta educativa de estudios avanzados de excelencia, para garantizar la inclusión, la pertinencia social y la alineación con las demandas de los sectores productivo, gubernamental y social. | F6: 15 | G6: Registrar 50 protocolos de investigación de alumnos de estudios avanzados con temáticas vinculadas a la Agenda Estratégica de Investigación, anualmente | H6: ACT-PRDI-NS-2847 | J6: Actividad | K6: Sin fórmula | L6: Registrar protocolos de investigación de alumnos de estudios avanzados con temáticas vinculadas a la Agenda Estratégica de Investigación | R6: =M6 -> 0 | S6: =N6 -> 0 | T6: =O6 -> 0 | U6: =P6 -> 0 | V6: =Q6 -> 0 | W6: Anual
A7: 5 | B7: PRDI25-29-Obj-37 | C7: Garantizar una formación en estudios avanzados de excelencia y pertinencia social, a través del desarrollo de programas innovadores con la integración de la investigación de la Agenda Estratégica de Investigación, para asegurar que el conocimiento generado impulse la transformación social. | D7: PRDI25-29-Obj-84 | E7: Consolidar una oferta educativa de estudios avanzados de excelencia, para garantizar la inclusión, la pertinencia social y la alineación con las demandas de los sectores productivo, gubernamental y social. | F7: 18 | G7: Generar protocolos de acción para incrementar la tasa de graduación y la eficiencia terminal en 10 espacios académicos, en 2026 | H7: ACT-PRDI-NS-2848 | J7: Actividad | K7: Sin fórmula | L7: Generar protocolos de acción para incrementar la tasa de graduación y la eficiencia terminal en espacios académicos | R7: =M7 -> 0 | S7: =N7 -> 0 | T7: =O7 -> 0 | U7: =P7 -> 0 | V7: =Q7 -> 0 | W7: Anual
A8: 6 | B8: PRDI25-29-Obj-37 | C8: Garantizar una formación en estudios avanzados de excelencia y pertinencia social, a través del desarrollo de programas innovadores con la integración de la investigación de la Agenda Estratégica de Investigación, para asegurar que el conocimiento generado impulse la transformación social. | D8: PRDI25-29-Obj-84 | E8: Consolidar una oferta educativa de estudios avanzados de excelencia, para garantizar la inclusión, la pertinencia social y la alineación con las demandas de los sectores productivo, gubernamental y social. | F8: 19 | G8: Incrementar a 1190 graduados de estudios avanzados, a 2029 | H8: ACT-PRDI-NS-2849 | J8: Actividad | K8: Sin fórmula | L8: Incrementar graduados de estudios avanzados | R8: =M8 -> 0 | S8: =N8 -> 0 | T8: =O8 -> 0 | U8: =P8 -> 0 | V8: =Q8 -> 0 | W8: Anual
A9: 7 | B9: PRDI25-29-Obj-37 | C9: Garantizar una formación en estudios avanzados de excelencia y pertinencia social, a través del desarrollo de programas innovadores con la integración de la investigación de la Agenda Estratégica de Investigación, para asegurar que el conocimiento generado impulse la transformación social. | D9: PRDI25-29-Obj-84 | E9: Consolidar una oferta educativa de estudios avanzados de excelencia, para garantizar la inclusión, la pertinencia social y la alineación con las demandas de los sectores productivo, gubernamental y social. | F9: 20 | G9: Incrementar a 17.56% la graduación de estudios avanzados por la opción de trabajo terminal de grado, a 2029 | H9: IND-PRDI-365 | J9: Indicador | K9: (Número de alumnos graduados por la opción de trabajo terminal de grado en el año que se reporta/Total de alumnos graduados en el año que se reporta)*100 | L9: Número de alumnos graduados por la opción de trabajo terminal de grado en el año que se reporta | R9: =IF(M10,M9/M10*100,"0") -> 0 | S9: =IF(N10,N9/N10*100,"0") -> 0 | T9: =IF(O10,O9/O10*100,"0") -> 0 | U9: =IF(P10,P9/P10*100,"0") -> 0 | V9: =IF(Q10,Q9/Q10*100,"0") -> 0 | W9: Anual
L10: Total de alumnos graduados en el año que se reporta)*100

Sheet 4 Investigación abierta
A1: N.P. | B1: Clave Objetivo General | C1: Objetivo General | D1: Clave Objetivo Específico | E1: Objetivo Específico | F1: No. de meta en el PRDI | G1: Meta PRDI | H1: Clave de la meta | I1: Meta del espacio académico | J1: Actividad/Indicador | K1: Método de cálculo | L1: Nombre de las variables | M1: Valor de las variables | R1: Valor de los indicadores | W1: Medición (anual o acumulada) | X1: Área responsable
M2: Ref. 2026 | N2: 2027 | O2: 2028 | P2: 2029 | Q2: 2030 | R2: Ref. 2026 | S2: 2027 | T2: 2028 | U2: 2029 | V2: 2030
A3: 1 | B3: PRDI25-29-Obj-38 | C3: Impulsar la investigación científica, humanística, tecnológica y de innovación priorizando la calidad, inclusión, equidad, retribución social y multilingüismo, a través del apoyo a proyectos sólidos, el fortalecimiento de redes en la comunidad investigadora y la optimización de recursos e infraestructura, en el marco del nuevo Modelo de Ciencia Abierta para la Transformación Social | D3: PRDI2025-2029-Obj-60 | E3: Fomentar la investigación abierta, equitativa y de calidad, así como transparentar su dimensión de retribución social, incentivar el diálogo de saberes y la participación activa de la comunidad universitaria de forma incluyente. | F3: 19 | G3: Contar con 200 CA de calidad, a 2028 | H3: ACT-PRDI-NS-2870 | I3: Mantener al menos 3 cuerpos académicos de calidad en cada medición anual de 2027 a 2030. | J3: Actividad | K3: Sin fórmula | L3: Contar con Cuerpos Académicos de calidad | M3: 3 | N3: 3 | O3: 3 | P3: 3 | Q3: 3 | R3: =IF(M3="","",M3) -> 3 | S3: =IF(N3="","",N3) -> 3 | T3: =IF(O3="","",O3) -> 3 | U3: =IF(P3="","",P3) -> 3 | V3: =IF(Q3="","",Q3) -> 3 | W3: Anual | X3: Por validar con el área responsable
A4: 2 | B4: PRDI25-29-Obj-38 | C4: Impulsar la investigación científica, humanística, tecnológica y de innovación priorizando la calidad, inclusión, equidad, retribución social y multilingüismo, a través del apoyo a proyectos sólidos, el fortalecimiento de redes en la comunidad investigadora y la optimización de recursos e infraestructura, en el marco del nuevo Modelo de Ciencia Abierta para la Transformación Social | D4: PRDI2025-2029-Obj-60 | E4: Fomentar la investigación abierta, equitativa y de calidad, así como transparentar su dimensión de retribución social, incentivar el diálogo de saberes y la participación activa de la comunidad universitaria de forma incluyente. | F4: 20 | G4: Mantener 98.68% de los CA que realizan investigación que contribuye a la solución de problemas sociales, a 2029 | H4: IND-PRDI-221 | J4: Indicador | K4: (Número de cuerpos académicos registrados en SEP que realizan investigación que contribuyen a la solución de problemas sociales/Total de cuerpos académicos registrados en SEP)*100 | L4: Número de cuerpos académicos registrados en SEP que realizan investigación que contribuyen a la solución de problemas sociales | R4: =IF(M5,M4/M5*100,"0") -> 0 | S4: =IF(N5,N4/N5*100,"0") -> 0 | T4: =IF(O5,O4/O5*100,"0") -> 0 | U4: =IF(P5,P4/P5*100,"0") -> 0 | V4: =IF(Q5,Q4/Q5*100,"0") -> 0 | W4: Anual
L5: Total de cuerpos académicos registrados en SEP
A6: 3 | B6: PRDI25-29-Obj-38 | C6: Impulsar la investigación científica, humanística, tecnológica y de innovación priorizando la calidad, inclusión, equidad, retribución social y multilingüismo, a través del apoyo a proyectos sólidos, el fortalecimiento de redes en la comunidad investigadora y la optimización de recursos e infraestructura, en el marco del nuevo Modelo de Ciencia Abierta para la Transformación Social | D6: PRDI2025-2029-Obj-60 | E6: Fomentar la investigación abierta, equitativa y de calidad, así como transparentar su dimensión de retribución social, incentivar el diálogo de saberes y la participación activa de la comunidad universitaria de forma incluyente. | F6: 21 | G6: Mantener el 49.59% de los PTC con participación en redes con pares extranjeros, anualmente | H6: IND-PRDI-368 | J6: Indicador | K6: (Número de Profesores de Tiempo Completo con participación en redes con pares extranjeros/Total de Profesores de Tiempo Completo)*100 | L6: Número de Profesores de Tiempo Completo con participación en redes con pares extranjeros | R6: =IF(M7,M6/M7*100,"0") -> 0 | S6: =IF(N7,N6/N7*100,"0") -> 0 | T6: =IF(O7,O6/O7*100,"0") -> 0 | U6: =IF(P7,P6/P7*100,"0") -> 0 | V6: =IF(Q7,Q6/Q7*100,"0") -> 0 | W6: Anual
L7: Total de Profesores de Tiempo Completo
A8: 4 | B8: PRDI25-29-Obj-38 | C8: Impulsar la investigación científica, humanística, tecnológica y de innovación priorizando la calidad, inclusión, equidad, retribución social y multilingüismo, a través del apoyo a proyectos sólidos, el fortalecimiento de redes en la comunidad investigadora y la optimización de recursos e infraestructura, en el marco del nuevo Modelo de Ciencia Abierta para la Transformación Social | D8: PRDI2025-2029-Obj-60 | E8: Fomentar la investigación abierta, equitativa y de calidad, así como transparentar su dimensión de retribución social, incentivar el diálogo de saberes y la participación activa de la comunidad universitaria de forma incluyente. | F8: 22 | G8: Mantener 49.81% de los PTC que participan en redes nacionales, anualmente | H8: IND-PRDI-370 | J8: Indicador | K8: (Número de Profesores de Tiempo Completo con participación en redes nacionales/Total de Profesores de Tiempo Completo)*100 | L8: Número de Profesores de Tiempo Completo con participación en redes nacionales | R8: =IF(M9,M8/M9*100,"0") -> 0 | S8: =IF(N9,N8/N9*100,"0") -> 0 | T8: =IF(O9,O8/O9*100,"0") -> 0 | U8: =IF(P9,P8/P9*100,"0") -> 0 | V8: =IF(Q9,Q8/Q9*100,"0") -> 0 | W8: Anual
L9: Total de Profesores de Tiempo Completo | M9: =M7 -> 0 | N9: =N7 -> 0 | O9: =O7 -> 0 | P9: =P7 -> 0 | Q9: =Q7 -> 0
A10: 5 | B10: PRDI25-29-Obj-38 | C10: Impulsar la investigación científica, humanística, tecnológica y de innovación priorizando la calidad, inclusión, equidad, retribución social y multilingüismo, a través del apoyo a proyectos sólidos, el fortalecimiento de redes en la comunidad investigadora y la optimización de recursos e infraestructura, en el marco del nuevo Modelo de Ciencia Abierta para la Transformación Social | D10: PRDI25-29-Obj-85 | E10: Optimizar el proceso de asignación y gestión de recursos financieros para consolidar la investigación con proyectos que respondan a los principios de calidad, equidad, inclusión, retribución social y multilingüismo. | F10: 3 | G10: Atender las necesidades prioritarias de mantenimiento, equipamiento y medidas de seguridad de 115 laboratorios de investigación, a 2029 | H10: ACT-PRDI-NS-2854 | J10: Actividad | K10: Sin fórmula | L10: Atender las necesidades prioritarias de mantenimiento, equipamiento y medidas de seguridad de laboratorios de investigación | R10: =M10 -> 0 | S10: =N10 -> 0 | T10: =O10 -> 0 | U10: =P10 -> 0 | V10: =Q10 -> 0 | W10: Anual
A11: 6 | B11: PRDI25-29-Obj-38 | C11: Impulsar la investigación científica, humanística, tecnológica y de innovación priorizando la calidad, inclusión, equidad, retribución social y multilingüismo, a través del apoyo a proyectos sólidos, el fortalecimiento de redes en la comunidad investigadora y la optimización de recursos e infraestructura, en el marco del nuevo Modelo de Ciencia Abierta para la Transformación Social | D11: PRDI25-29-Obj-85 | E11: Optimizar el proceso de asignación y gestión de recursos financieros para consolidar la investigación con proyectos que respondan a los principios de calidad, equidad, inclusión, retribución social y multilingüismo. | F11: 7 | G11: Promover la participación en 2 convocatorias externas de proyectos de investigación, anualmente | H11: ACT-PRDI-NS-2858 | J11: Actividad | K11: Sin fórmula | L11: Promover la participación en convocatorias externas de proyectos de investigación | R11: =M11 -> 0 | S11: =N11 -> 0 | T11: =O11 -> 0 | U11: =P11 -> 0 | V11: =Q11 -> 0 | W11: Anual
A12: 7 | B12: PRDI25-29-Obj-38 | C12: Impulsar la investigación científica, humanística, tecnológica y de innovación priorizando la calidad, inclusión, equidad, retribución social y multilingüismo, a través del apoyo a proyectos sólidos, el fortalecimiento de redes en la comunidad investigadora y la optimización de recursos e infraestructura, en el marco del nuevo Modelo de Ciencia Abierta para la Transformación Social | D12: PRDI25-29-Obj-85 | E12: Optimizar el proceso de asignación y gestión de recursos financieros para consolidar la investigación con proyectos que respondan a los principios de calidad, equidad, inclusión, retribución social y multilingüismo. | F12: 17 | G12: Contar con 19.51% de los proyectos de investigación en DT e innovación que cuenten con un plan de transferencia, innovación o impacto social documentado, a 2029 | H12: IND-PRDI-367 | J12: Indicador | K12: (Número de proyectos de investigación en DT e Innovación que cuentan con plan de transferencia, innovación impacto social documentado/Total de proyectos de investigación en DT e Innovación)*100 | L12: Número de proyectos de investigación en DT e Innovación que cuentan con plan de transferencia, innovación impacto social documentado | R12: =IF(M13,M12/M13*100,"0") -> 0 | S12: =IF(N13,N12/N13*100,"0") -> 0 | T12: =IF(O13,O12/O13*100,"0") -> 0 | U12: =IF(P13,P12/P13*100,"0") -> 0 | V12: =IF(Q13,Q12/Q13*100,"0") -> 0 | W12: Anual
L13: Total de proyectos de investigación en DT e Innovación
A14: 8 | B14: PRDI25-29-Obj-38 | C14: Impulsar la investigación científica, humanística, tecnológica y de innovación priorizando la calidad, inclusión, equidad, retribución social y multilingüismo, a través del apoyo a proyectos sólidos, el fortalecimiento de redes en la comunidad investigadora y la optimización de recursos e infraestructura, en el marco del nuevo Modelo de Ciencia Abierta para la Transformación Social | D14: PRDI25-29-Obj-85 | E14: Optimizar el proceso de asignación y gestión de recursos financieros para consolidar la investigación con proyectos que respondan a los principios de calidad, equidad, inclusión, retribución social y multilingüismo. | F14: 18 | G14: Contar con 53.22% de producción científica con sentido social, anualmente | H14: IND-PRDI-225 | J14: Indicador | K14: (Número de producción científica con sentido social/Total de la producción científica reportada)*100 | L14: Número de producción científica con sentido social | R14: =IF(M15,M14/M15*100,"0") -> 0 | S14: =IF(N15,N14/N15*100,"0") -> 0 | T14: =IF(O15,O14/O15*100,"0") -> 0 | U14: =IF(P15,P14/P15*100,"0") -> 0 | V14: =IF(Q15,Q14/Q15*100,"0") -> 0 | W14: Anual
L15: Total de la producción científica reportada

Sheet 5 Innovación, desarrollo tec
A1: N.P. | B1: Clave Objetivo General | C1: Objetivo General | D1: Clave Objetivo Específico | E1: Objetivo Específico | F1: No. de meta en el PRDI | G1: Meta PRDI | H1: Clave de la meta | I1: Meta del espacio académico | J1: Actividad/Indicador | K1: Método de cálculo | L1: Nombre de las variables | M1: Valor de las variables | R1: Valor de los indicadores | W1: Medición (anual o acumulada) | X1: Área responsable
M2: Ref. 2026 | N2: 2027 | O2: 2028 | P2: 2029 | Q2: 2030 | R2: Ref. 2026 | S2: 2027 | T2: 2028 | U2: 2029 | V2: 2030
A3: 1 | B3: PRDI25-29-Obj-39 | C3: Impulsar la innovación y el desarrollo tecnológico de manera sostenible y equitativa, a través de la articulación de plataformas multiactor, la gestión de la propiedad intelectual y transferencia tecnológica, en el marco de proyectos Penta-Hélice. | D3: PRDI25-29-Obj-86 | E3: Fortalecer la gestión institucional de la propiedad intelectual y transferencia tecnológica a través de mecanismos equitativos, sostenibles y con retribución social. | F3: 1 | G3: Contar con 222 expedientes, registros y patentes ante el IMPI, a 2029 | H3: ACT-PRDI-NS-2875 | J3: Actividad | K3: Sin fórmula | L3: Contar con expedientes, registros y patentes ante el IMPI | R3: =M3 -> 0 | S3: =N3 -> 0 | T3: =O3 -> 0 | U3: =P3 -> 0 | V3: =Q3 -> 0 | W3: Anual
A4: 2 | B4: PRDI25-29-Obj-39 | C4: Impulsar la innovación y el desarrollo tecnológico de manera sostenible y equitativa, a través de la articulación de plataformas multiactor, la gestión de la propiedad intelectual y transferencia tecnológica, en el marco de proyectos Penta-Hélice. | D4: PRDI25-29-Obj-86 | E4: Fortalecer la gestión institucional de la propiedad intelectual y transferencia tecnológica a través de mecanismos equitativos, sostenibles y con retribución social. | F4: 7 | G4: Capacitar a 100 miembros de la comunidad universitaria en materia de propiedad intelectual y gestión de activos de conocimiento, anualmente | H4: ACT-PRDI-NS-2881 | J4: Actividad | K4: Sin fórmula | L4: Capacitar a miembros de la comunidad universitaria en materia de propiedad intelectual y gestión de activos de conocimiento | R4: =M4 -> 0 | S4: =N4 -> 0 | T4: =O4 -> 0 | U4: =P4 -> 0 | V4: =Q4 -> 0 | W4: Anual

Sheet 6 Dif y divulga de la ciencia
A1: N.P. | B1: Clave Objetivo General | C1: Objetivo General | D1: Clave Objetivo Específico | E1: Objetivo Específico | F1: No. de meta en el PRDI | G1: Meta PRDI | H1: Clave de la meta | I1: Meta del espacio académico | J1: Actividad/Indicador | K1: Método de cálculo | L1: Nombre de las variables | M1: Valor de las variables | R1: Valor de los indicadores | W1: Medición (anual o acumulada) | X1: Área responsable
M2: Ref. 2026 | N2: 2027 | O2: 2028 | P2: 2029 | Q2: 2030 | R2: Ref. 2026 | S2: 2027 | T2: 2028 | U2: 2029 | V2: 2030
A3: 2 | B3: PRDI25-29-Obj-40 | C3: Comunicar en abierto los resultados de investigación con la finalidad de democratizar el acceso al conocimiento generado en la Universidad y asegurar su máxima difusión y retribución social en formatos accesibles y multilingües que se posicionen como bien público digital. | D3: PRDI25-29-Obj-87 | E3: Fortalecer los procesos editoriales y tecnológicos para sostener y generar libros y revistas científicas como bienes públicos digitales. | F3: 6 | G3: Realizar 1 programa de sostenibilidad y fortalecimiento del Acceso Abierto no comercial para las revistas científicas editadas en la Universidad, anualmente | H3: ACT-PRDI-NS-2890 | J3: Actividad | K3: Sin fórmula | L3: Realizar un programa de sostenibilidad y fortalecimiento del Acceso Abierto no comercial para las revistas científicas editadas en la Universidad | R3: =M3 -> 0 | S3: =N3 -> 0 | T3: =O3 -> 0 | U3: =P3 -> 0 | V3: =Q3 -> 0 | W3: Anual
A4: 3 | B4: PRDI25-29-Obj-40 | C4: Comunicar en abierto los resultados de investigación con la finalidad de democratizar el acceso al conocimiento generado en la Universidad y asegurar su máxima difusión y retribución social en formatos accesibles y multilingües que se posicionen como bien público digital. | D4: PRDI25-29-Obj-87 | E4: Fortalecer los procesos editoriales y tecnológicos para sostener y generar libros y revistas científicas como bienes públicos digitales. | F4: 13 | G4: Capacitar a 1000 miembros de la comunidad universitaria en Ciencia Abierta, anualmente | H4: ACT-PRDI-NS-2897 | J4: Actividad | K4: Sin fórmula | L4: Capacitar a miembros de la comunidad universitaria en Ciencia Abierta | R4: =M4 -> 0 | S4: =N4 -> 0 | T4: =O4 -> 0 | U4: =P4 -> 0 | V4: =Q4 -> 0 | W4: Anual
A5: 4 | B5: PRDI25-29-Obj-40 | C5: Comunicar en abierto los resultados de investigación con la finalidad de democratizar el acceso al conocimiento generado en la Universidad y asegurar su máxima difusión y retribución social en formatos accesibles y multilingües que se posicionen como bien público digital. | D5: PRDI25-29-Obj-87 | E5: Fortalecer los procesos editoriales y tecnológicos para sostener y generar libros y revistas científicas como bienes públicos digitales. | F5: 15 | G5: Realizar 1 evaluación de la calidad, criterios y políticas de Acceso Abierto Diamante de las publicaciones periódicas científicas institucionales, anualmente | H5: ACT-PRDI-NS-2899 | J5: Actividad | K5: Sin fórmula | L5: Realizar evaluaciones de la calidad, criterios y políticas de Acceso Abierto Diamante de las publicaciones periódicas científicas institucionales | R5: =M5 -> 0 | S5: =N5 -> 0 | T5: =O5 -> 0 | U5: =P5 -> 0 | V5: =Q5 -> 0 | W5: Anual

Sheet 7 Cultura desarrollo integral
A1: N.P. | B1: Clave Objetivo General | C1: Objetivo General | D1: Clave Objetivo Específico | E1: Objetivo Específico | F1: No. de meta en el PRDI | G1: Meta PRDI | H1: Clave de la meta | I1: Meta del espacio académico | J1: Actividad/Indicador | K1: Método de cálculo | L1: Nombre de las variables | M1: Valor de las variables | R1: Valor de los indicadores | W1: Medición (anual o acumulada) | X1: Área responsable
M2: Ref. 2026 | N2: 2027 | O2: 2028 | P2: 2029 | Q2: 2030 | R2: Ref. 2026 | S2: 2027 | T2: 2028 | U2: 2029 | V2: 2030
A3: 1 | B3: PRDI25-29-Obj-41 | C3: PRDI25-29-Obj-41 -Fortalecer la cultura a través de proyectos y actividades que articulen la expresión artística y cultural como parte del desarrollo de la comunidad universitaria.. | D3: PRDI25-29-Obj-63 | E3: Fomentar la participación activa de la comunidad universitaria y sociedad en general en actividades culturales innovadoras que fortalezcan la identidad y el sentido de pertenencia institucional que contribuyan a la cohesión social y la igualdad. | F3: 2 | G3: Abrir 850 talleres culturales anualmente en beneficio de la colectividad universitaria de nivel superior | H3: ACT-PRDI-NS-3193 | J3: Actividad | K3: Sin fórmula | L3: Abrir talleres culturales en beneficio de la colectividad universitaria de nivel superior | R3: =M3 -> 0 | S3: =N3 -> 0 | T3: =O3 -> 0 | U3: =P3 -> 0 | V3: =Q3 -> 0 | W3: Anual
A4: 2 | B4: PRDI25-29-Obj-41 | C4: PRDI25-29-Obj-41 -Fortalecer la cultura a través de proyectos y actividades que articulen la expresión artística y cultural como parte del desarrollo de la comunidad universitaria.. | D4: PRDI25-29-Obj-63 | E4: Fomentar la participación activa de la comunidad universitaria y sociedad en general en actividades culturales innovadoras que fortalezcan la identidad y el sentido de pertenencia institucional que contribuyan a la cohesión social y la igualdad. | F4: 4 | G4: Realizar 850 presentaciones artísticas anualmente. | H4: ACT-PRDI-NS-1816 | J4: Actividad | K4: Sin fórmula | L4: Realizar presentaciones artísticas | R4: =M4 -> 0 | S4: =N4 -> 0 | T4: =O4 -> 0 | U4: =P4 -> 0 | V4: =Q4 -> 0 | W4: Anual
A5: 3 | B5: PRDI25-29-Obj-41 | C5: PRDI25-29-Obj-41 -Fortalecer la cultura a través de proyectos y actividades que articulen la expresión artística y cultural como parte del desarrollo de la comunidad universitaria.. | D5: PRDI25-29-Obj-63 | E5: Fomentar la participación activa de la comunidad universitaria y sociedad en general en actividades culturales innovadoras que fortalezcan la identidad y el sentido de pertenencia institucional que contribuyan a la cohesión social y la igualdad. | F5: 8 | G5: Organizar 3 programas de fortalecimiento al talento audiovisual para desarrollar la creatividad cultural de los universitarios, durante la administración | H5: ACT-PRDI-NS-3195 | J5: Actividad | K5: Sin fórmula | L5: Organizar programas de fortalecimiento al talento audiovisual para desarrollar la creatividad cultural de los universitarios | R5: =M5 -> 0 | S5: =N5 -> 0 | T5: =O5 -> 0 | U5: =P5 -> 0 | V5: =Q5 -> 0 | W5: Anual
A6: 4 | B6: PRDI25-29-Obj-41 | C6: PRDI25-29-Obj-41 -Fortalecer la cultura a través de proyectos y actividades que articulen la expresión artística y cultural como parte del desarrollo de la comunidad universitaria.. | D6: PRDI25-29-Obj-88 | E6: Fortalecer espacios de formación y reflexión que integren a la cultura con inclusión y transformación social. | F6: 15 | G6: Organizar 6 programas audiovisuales vanguardistas que fomenten la innovación cultural durante la administración | H6: ACT-PRDI-NS-3200 | J6: Actividad | K6: Sin fórmula | L6: Organizar programas audiovisuales vanguardistas que fomenten la innovación cultural | R6: =M6 -> 0 | S6: =N6 -> 0 | T6: =O6 -> 0 | U6: =P6 -> 0 | V6: =Q6 -> 0 | W6: Anual
A7: 5 | B7: PRDI25-29-Obj-41 | C7: PRDI25-29-Obj-41 -Fortalecer la cultura a través de proyectos y actividades que articulen la expresión artística y cultural como parte del desarrollo de la comunidad universitaria.. | D7: PRDI25-29-Obj-88 | E7: Fortalecer espacios de formación y reflexión que integren a la cultura con inclusión y transformación social. | F7: 17 | G7: Realizar al año, 4 programas artísticos que contribuyan al fortalecimiento cultural de la comunidad universitaria | H7: ACT-PRDI-NS-3202 | J7: Actividad | K7: Sin fórmula | L7: Realizar programas artísticos que contribuyan al fortalecimiento cultural de la comunidad universitaria | R7: =M7 -> 0 | S7: =N7 -> 0 | T7: =O7 -> 0 | U7: =P7 -> 0 | V7: =Q7 -> 0 | W7: Anual
A8: 6 | B8: PRDI25-29-Obj-41 | C8: PRDI25-29-Obj-41 -Fortalecer la cultura a través de proyectos y actividades que articulen la expresión artística y cultural como parte del desarrollo de la comunidad universitaria.. | D8: PRDI25-29-Obj-88 | E8: Fortalecer espacios de formación y reflexión que integren a la cultura con inclusión y transformación social. | F8: 20 | G8: Realizar al año 1 festival cultural que reúna a los talentos de distintos talleres y espacios académicos | H8: ACT-PRDI-NS-3205 | J8: Actividad | K8: Sin fórmula | L8: Realizar festivales culturales que reúna a los talentos de distintos talleres y espacios académicos | R8: =M8 -> 0 | S8: =N8 -> 0 | T8: =O8 -> 0 | U8: =P8 -> 0 | V8: =Q8 -> 0 | W8: Anual

Sheet 8 Deporte universitario
A1: N.P. | B1: Clave Objetivo General | C1: Objetivo General | D1: Clave Objetivo Específico | E1: Objetivo Específico | F1: No. de meta en el PRDI | G1: Meta PRDI | H1: Clave de la meta | I1: Meta del espacio académico | J1: Actividad/Indicador | K1: Método de cálculo | L1: Nombre de las variables | M1: Valor de las variables | R1: Valor de los indicadores | W1: Medición (anual o acumulada) | X1: Área responsable
M2: Ref. 2026 | N2: 2027 | O2: 2028 | P2: 2029 | Q2: 2030 | R2: Ref. 2026 | S2: 2027 | T2: 2028 | U2: 2029 | V2: 2030
A3: 1 | B3: PRDI25-29-Obj-42 | C3: Fortalecer, mediante la promoción y participación, una cultura física para favorecer el desarrollo integral y la adopción de hábitos de bienestar en la comunidad universitaria. | D3: PRDI25-29-Obj-64 | E3: Generar la cultura física en la comunidad universitaria para fomentar hábitos de vida saludable. | F3: 1 | G3: Organizar anualmente 12 eventos regionales que promuevan el bienestar, el autocuidado y la actividad física responsable | H3: ACT-PRDI-NS-2746 | J3: Actividad | K3: Sin fórmula | L3: Organizar eventos regionales que promuevan el bienestar, el autocuidado y la actividad física responsable | R3: =M3 -> 0 | S3: =N3 -> 0 | T3: =O3 -> 0 | U3: =P3 -> 0 | V3: =Q3 -> 0 | W3: Anual
