Workbook
Name _Toc82616607: '2 EstudiantadoEstProf'!#REF!

Sheet 2 EstudiantadoEstProf
A1: N.P. | B1: Clave Objetivo General | C1: Objetivo General | D1: Clave Objetivo Específico | E1: Objetivo Específico | F1: No. de meta en el PRDI | G1: Meta PRDI | H1: Clave de la meta | I1: Meta del espacio académico | J1: Actividad/Indicador | K1: Método de cálculo | L1: Nombre de las variables | M1: Valor de las variables | R1: Valor de los indicadores | W1: Medición (anual o acumulada) | X1: Área responsable | AN1: ESTATUS
M2: Ref. 2026 | N2: 2027 | O2: 2028 | P2: 2029 | Q2: 2030 | R2: Ref. 2026 | S2: 2027 | T2: 2028 | U2: 2029 | V2: 2030
A3: 1 | B3: PRDI25-29-Obj-36 | C3: Formar estudiantes de excelencia, a través de estudios profesionales pertinentes e inclusivos, con una vinculación permanente con estudiantes y personas egresadas, para su pleno desarrollo profesional y su contribución al bienestar social. | D3: PRDI2025-2029-Obj-58 | E3: Contar con planes de estudio pertinentes y de excelencia, en diferentes modalidades, que incorporen los criterios transversales del SEAES, de indicadores de instancias de evaluación externa y acreditación, y de organismos acreditadores, para formar profesionistas que contribuyan a la conformación de una sociedad más justa, libre, incluyente y pacífica, con una visión de sostenibilidad. | F3: 3 | G3: Incorporar contenidos temáticos o actividades académicas sobre los criterios transversales del seaes, en 30 planes de estudio reestructurados, durante la administración | H3: ACT-PRDI-NS-2726 | I3: Contribuir desde la Facultad de Ingeniería al cumplimiento de la meta PRDI “Incorporar contenidos temáticos o actividades académicas sobre los criterios transversales del seaes, en 30 planes de estudio reestructurados, durante la administración”, con valores absolutos programados de 2027: 1, 2028: 0, 2029: 0, 2030: 0. | J3: Actividad | K3: Sin fórmula | L3: Incorporar contenidos temáticos o actividades académicas sobre los criterios transversales del seaes, en planes de estudio reestructurados | N3: 1 | O3: 0 | P3: 0 | Q3: 0 | R3: =IF(M3="","",M3) | S3: =IF(N3="","",N3) -> 1 | T3: =IF(O3="","",O3) -> 0 | U3: =IF(P3="","",P3) -> 0 | V3: =IF(Q3="","",Q3) -> 0 | W3: Anual | X3: Subdirección Académica y coordinaciones de licenciatura
A4: 2 | B4: PRDI25-29-Obj-36 | C4: Formar estudiantes de excelencia, a través de estudios profesionales pertinentes e inclusivos, con una vinculación permanente con estudiantes y personas egresadas, para su pleno desarrollo profesional y su contribución al bienestar social. | D4: PRDI2025-2029-Obj-58 | E4: Contar con planes de estudio pertinentes y de excelencia, en diferentes modalidades, que incorporen los criterios transversales del SEAES, de indicadores de instancias de evaluación externa y acreditación, y de organismos acreditadores, para formar profesionistas que contribuyan a la conformación de una sociedad más justa, libre, incluyente y pacífica, con una visión de sostenibilidad. | F4: 4 | G4: Contar con el acervo de 120 unidades de aprendizaje de estudios profesionales apegados a las referencias documentales básicas durante la administración | H4: ACT-PRDI-NS-2727 | I4: Contribuir desde la Facultad de Ingeniería al cumplimiento de la meta PRDI “Contar con el acervo de 120 unidades de aprendizaje de estudios profesionales apegados a las referencias documentales básicas durante la administración”, con valores absolutos programados de 2027: 1, 2028: 1, 2029: 1, 2030: 0. | J4: Actividad | K4: Sin fórmula | L4: Contar con el acervo de unidades de aprendizaje de estudios profesionales apegados a las referencias documentales básicas | N4: 1 | O4: 1 | P4: 1 | Q4: 0 | R4: =IF(M4="","",M4) | S4: =IF(N4="","",N4) -> 1 | T4: =IF(O4="","",O4) -> 1 | U4: =IF(P4="","",P4) -> 1 | V4: =IF(Q4="","",Q4) -> 0 | W4: Anual | X4: Subdirección Académica y coordinaciones de licenciatura
A5: 3 | B5: PRDI25-29-Obj-36 | C5: Formar estudiantes de excelencia, a través de estudios profesionales pertinentes e inclusivos, con una vinculación permanente con estudiantes y personas egresadas, para su pleno desarrollo profesional y su contribución al bienestar social. | D5: PRDI2025-2029-Obj-58 | E5: Contar con planes de estudio pertinentes y de excelencia, en diferentes modalidades, que incorporen los criterios transversales del SEAES, de indicadores de instancias de evaluación externa y acreditación, y de organismos acreditadores, para formar profesionistas que contribuyan a la conformación de una sociedad más justa, libre, incluyente y pacífica, con una visión de sostenibilidad. | F5: 7 | G5: Lograr que 89.13% de los programas educativos de estudios profesionales evaluables cuenten con reconocimiento por su excelencia, para 2029 | H5: IND-NS-210 | I5: Mejorar o mantener de forma conservadora en la Facultad de Ingeniería el indicador IND-NS-210, con la trayectoria 2027: 80%, 2028: 80%, 2029: 80%, 2030: 80%, sustentada en referencia PRDI; no existe serie histórica directamente comparable para la variable. | J5: Indicador | K5: (Número de programas educativos de estudios profesionales con reconocimiento por su excelencia / Número de programas educativos de Estudios Profesionales evaluables)*100 | L5: Número de programas educativos de estudios profesionales con reconocimiento por su excelencia | N5: 4 | O5: 4 | P5: 4 | Q5: 4 | R5: =IF(M6,M5/M6*100,"") | S5: =IF(N6,N5/N6*100,"") -> 80 | T5: =IF(O6,O5/O6*100,"") -> 80 | U5: =IF(P6,P5/P6*100,"") -> 80 | V5: =IF(Q6,Q5/Q6*100,"") -> 80 | W5: Anual | X5: Subdirección Académica y coordinaciones de licenciatura
L6: Número de programas educativos de Estudios Profesionales evaluables | N6: 5 | O6: 5 | P6: 5 | Q6: 5
A7: 4 | B7: PRDI25-29-Obj-36 | C7: Formar estudiantes de excelencia, a través de estudios profesionales pertinentes e inclusivos, con una vinculación permanente con estudiantes y personas egresadas, para su pleno desarrollo profesional y su contribución al bienestar social. | D7: PRDI2025-2029-Obj-58 | E7: Contar con planes de estudio pertinentes y de excelencia, en diferentes modalidades, que incorporen los criterios transversales del SEAES, de indicadores de instancias de evaluación externa y acreditación, y de organismos acreditadores, para formar profesionistas que contribuyan a la conformación de una sociedad más justa, libre, incluyente y pacífica, con una visión de sostenibilidad. | F7: 8 | G7: Lograr que 92.9% de la matrícula en programas educativos de estudios profesionales evaluables, curse en programas educativos reconocidos por su excelencia, para 2029 | H7: IND-PRDI-351 | I7: Mejorar o mantener de forma conservadora en la Facultad de Ingeniería el indicador IND-PRDI-351, con la trayectoria 2027: 88.89%, 2028: 90.25%, 2029: 91.55%, 2030: 92.91%, sustentada en referencia PRDI; no existe serie histórica directamente comparable para la variable. | J7: Indicador | K7: (Matrícula de estudiantes de estudios profesionales del sistema dependiente en programas educativos reconocidos por su excelencia / Matrícula de estudiantes de estudios profesionales del sistema dependiente en programas educativos evaluables)*100 | L7: Matrícula de estudiantes de estudios profesionales del sistema dependiente en programas educativos reconocidos por su excelencia | N7: 2657 | O7: 2711 | P7: 2764 | Q7: 2819 | R7: =IF(M8,M7/M8*100,"") | S7: =IF(N8,N7/N8*100,"") -> 88.892606 | T7: =IF(O8,O7/O8*100,"") -> 90.246338 | U7: =IF(P8,P7/P8*100,"") -> 91.553495 | V7: =IF(Q8,Q7/Q8*100,"") -> 92.913645 | W7: Anual | X7: Subdirección Académica y coordinaciones de licenciatura
L8: Matrícula de estudiantes de estudios profesionales del sistema dependiente en programas educativos evaluables | N8: 2989 | O8: 3004 | P8: 3019 | Q8: 3034
A9: 5 | B9: PRDI25-29-Obj-36 | C9: Formar estudiantes de excelencia, a través de estudios profesionales pertinentes e inclusivos, con una vinculación permanente con estudiantes y personas egresadas, para su pleno desarrollo profesional y su contribución al bienestar social. | D9: PRDI25-29-Obj-81 | E9: Fortalecer la formación disciplinar e integral del estudiantado y su educación continua, en congruencia con el modelo educativo institucional, para fomentar su desarrollo humano completo y maximizar su potencial académico y profesional, así como su retribución social, en los diferentes sectores. | F9: 9 | G9: Lograr que 72% de los sustentantes que presentan el EGEL obtengan testimonios de desempeño sobresaliente o satisfactorio, para 2029 | H9: IND-PRDI-200 | I9: Mejorar o mantener de forma conservadora en la Facultad de Ingeniería el indicador IND-PRDI-200, con la trayectoria 2027: 68%, 2028: 70%, 2029: 71.29%, 2030: 71.57%, sustentada en referencia PRDI; no existe serie histórica directamente comparable para la variable. | J9: Indicador | K9: (Número de sustentantes de estudios profesionales que obtienen testimonio de desempeño sobresaliente o satisfactorio en el EGEL / Total de sustentantes de estudios profesionales que presentan los EGEL)*100 | L9: Número de sustentantes de estudios profesionales que obtienen testimonio de desempeño sobresaliente o satisfactorio en el EGEL | N9: 68 | O9: 70 | P9: 72 | Q9: 73 | R9: =IF(M10,M9/M10*100,"") | S9: =IF(N10,N9/N10*100,"") -> 68 | T9: =IF(O10,O9/O10*100,"") -> 70 | U9: =IF(P10,P9/P10*100,"") -> 71.287129 | V9: =IF(Q10,Q9/Q10*100,"") -> 71.568627 | W9: Anual | X9: Subdirección Académica y coordinaciones de licenciatura
L10: Total de sustentantes de estudios profesionales que presentan los EGEL | N10: 100 | O10: 100 | P10: 101 | Q10: 102
A11: 6 | B11: PRDI25-29-Obj-36 | C11: Formar estudiantes de excelencia, a través de estudios profesionales pertinentes e inclusivos, con una vinculación permanente con estudiantes y personas egresadas, para su pleno desarrollo profesional y su contribución al bienestar social. | D11: PRDI25-29-Obj-81 | E11: Fortalecer la formación disciplinar e integral del estudiantado y su educación continua, en congruencia con el modelo educativo institucional, para fomentar su desarrollo humano completo y maximizar su potencial académico y profesional, así como su retribución social, en los diferentes sectores. | F11: 10 | G11: Implementar 1 programa de preparación para EGEL anualmente | H11: ACT-PRDI-NS-2781 | I11: Contribuir desde la Facultad de Ingeniería al cumplimiento de la meta PRDI “Implementar 1 programa de preparación para EGEL anualmente”, con valores absolutos programados de 2027: 1, 2028: 1, 2029: 1, 2030: 1. | J11: Actividad | K11: Sin fórmula | L11: Implementar un programa de preparación para EGEL | M11: 0 | N11: 1 | O11: 1 | P11: 1 | Q11: 1 | R11: =IF(M11="","",M11) -> 0 | S11: =IF(N11="","",N11) -> 1 | T11: =IF(O11="","",O11) -> 1 | U11: =IF(P11="","",P11) -> 1 | V11: =IF(Q11="","",Q11) -> 1 | W11: Anual | X11: Subdirección Académica y coordinaciones de licenciatura
A12: 7 | B12: PRDI25-29-Obj-36 | C12: Formar estudiantes de excelencia, a través de estudios profesionales pertinentes e inclusivos, con una vinculación permanente con estudiantes y personas egresadas, para su pleno desarrollo profesional y su contribución al bienestar social. | D12: PRDI25-29-Obj-81 | E12: Fortalecer la formación disciplinar e integral del estudiantado y su educación continua, en congruencia con el modelo educativo institucional, para fomentar su desarrollo humano completo y maximizar su potencial académico y profesional, así como su retribución social, en los diferentes sectores. | F12: 14 | G12: Lograr que 550 estudiantes de estudios profesionales participen en movilidad intrainstitucional durante la administración | H12: ACT-PRDI-NS-2785 | I12: Contribuir desde la Facultad de Ingeniería al cumplimiento de la meta PRDI “Lograr que 550 estudiantes de estudios profesionales participen en movilidad intrainstitucional durante la administración”, con valores absolutos programados de 2027: 3, 2028: 3, 2029: 2, 2030: 2. | J12: Actividad | K12: Sin fórmula | L12: Lograr que estudiantes de estudios profesionales participen en movilidad intrainstitucional | N12: 3 | O12: 3 | P12: 2 | Q12: 2 | R12: =IF(M12="","",M12) | S12: =IF(N12="","",N12) -> 3 | T12: =IF(O12="","",O12) -> 3 | U12: =IF(P12="","",P12) -> 2 | V12: =IF(Q12="","",Q12) -> 2 | W12: Anual | X12: Subdirección Académica y coordinaciones de licenciatura
A13: 8 | B13: PRDI25-29-Obj-36 | C13: Formar estudiantes de excelencia, a través de estudios profesionales pertinentes e inclusivos, con una vinculación permanente con estudiantes y personas egresadas, para su pleno desarrollo profesional y su contribución al bienestar social. | D13: PRDI25-29-Obj-81 | E13: Fortalecer la formación disciplinar e integral del estudiantado y su educación continua, en congruencia con el modelo educativo institucional, para fomentar su desarrollo humano completo y maximizar su potencial académico y profesional, así como su retribución social, en los diferentes sectores. | F13: 15 | G13: Lograr anualmente que 100% de los estudiantes de estudios profesionales estén beneficiados con el nuevo Programa Institucional de Tutoría Académica | H13: IND-PRDI-353 | I13: Mejorar o mantener de forma conservadora en la Facultad de Ingeniería el indicador IND-PRDI-353, con la trayectoria 2027: 98.13%, 2028: 98.74%, 2029: 99.37%, 2030: 100%, sustentada en serie histórica directamente comparable del sitio. | J13: Indicador | K13: (Número de estudiantes de estudios profesionales beneficiados con tutoría/ Total de estudiantes de estudios profesionales) * 100 | L13: Número de estudiantes de estudios profesionales beneficiados con tutoría | N13: 2933 | O13: 2966 | P13: 3000 | Q13: 3034 | R13: =IF(M14,M13/M14*100,"") | S13: =IF(N14,N13/N14*100,"") -> 98.126464 | T13: =IF(O14,O13/O14*100,"") -> 98.73502 | U13: =IF(P14,P13/P14*100,"") -> 99.370653 | V13: =IF(Q14,Q13/Q14*100,"") -> 100 | W13: Anual | X13: Subdirección Académica y coordinaciones de licenciatura
L14: Total de estudiantes de estudios profesionales | N14: 2989 | O14: 3004 | P14: 3019 | Q14: 3034
A15: 9 | B15: PRDI25-29-Obj-36 | C15: Formar estudiantes de excelencia, a través de estudios profesionales pertinentes e inclusivos, con una vinculación permanente con estudiantes y personas egresadas, para su pleno desarrollo profesional y su contribución al bienestar social. | D15: PRDI25-29-Obj-81 | E15: Fortalecer la formación disciplinar e integral del estudiantado y su educación continua, en congruencia con el modelo educativo institucional, para fomentar su desarrollo humano completo y maximizar su potencial académico y profesional, así como su retribución social, en los diferentes sectores. | F15: 17 | G15: Lograr que 1 030 estudiantes de estudios profesionales participen en movilidad nacional e internacional durante la administración | H15: ACT-PRDI-NS-2789 | I15: Contribuir desde la Facultad de Ingeniería al cumplimiento de la meta PRDI “Lograr que 1 030 estudiantes de estudios profesionales participen en movilidad nacional e internacional durante la administración”, con valores absolutos programados de 2027: 5, 2028: 5, 2029: 5, 2030: 4. | J15: Actividad | K15: Sin fórmula | L15: Lograr que estudiantes de estudios profesionales participen en movilidad nacional e internacional | N15: 5 | O15: 5 | P15: 5 | Q15: 4 | R15: =IF(M15="","",M15) | S15: =IF(N15="","",N15) -> 5 | T15: =IF(O15="","",O15) -> 5 | U15: =IF(P15="","",P15) -> 5 | V15: =IF(Q15="","",Q15) -> 4 | W15: Anual | X15: Subdirección Académica y coordinaciones de licenciatura
A16: 10 | B16: PRDI25-29-Obj-36 | C16: Formar estudiantes de excelencia, a través de estudios profesionales pertinentes e inclusivos, con una vinculación permanente con estudiantes y personas egresadas, para su pleno desarrollo profesional y su contribución al bienestar social. | D16: PRDI25-29-Obj-81 | E16: Fortalecer la formación disciplinar e integral del estudiantado y su educación continua, en congruencia con el modelo educativo institucional, para fomentar su desarrollo humano completo y maximizar su potencial académico y profesional, así como su retribución social, en los diferentes sectores. | F16: 19 | G16: Realizar anualmente en los 55 espacios académicos un proyecto colaborativo de beneficio social | H16: ACT-PRDI-NS-2729 | I16: Contribuir desde la Facultad de Ingeniería al cumplimiento de la meta PRDI “Realizar anualmente en los 55 espacios académicos un proyecto colaborativo de beneficio social”, con valores absolutos programados de 2027: 1, 2028: 1, 2029: 1, 2030: 1. | J16: Actividad | K16: Sin fórmula | L16: Realizar en los espacios académicos un proyecto colaborativo de beneficio social | N16: 1 | O16: 1 | P16: 1 | Q16: 1 | R16: =IF(M16="","",M16) | S16: =IF(N16="","",N16) -> 1 | T16: =IF(O16="","",O16) -> 1 | U16: =IF(P16="","",P16) -> 1 | V16: =IF(Q16="","",Q16) -> 1 | W16: Anual | X16: Subdirección Académica y coordinaciones de licenciatura
A17: 11 | B17: PRDI25-29-Obj-36 | C17: Formar estudiantes de excelencia, a través de estudios profesionales pertinentes e inclusivos, con una vinculación permanente con estudiantes y personas egresadas, para su pleno desarrollo profesional y su contribución al bienestar social. | D17: PRDI25-29-Obj-81 | E17: Fortalecer la formación disciplinar e integral del estudiantado y su educación continua, en congruencia con el modelo educativo institucional, para fomentar su desarrollo humano completo y maximizar su potencial académico y profesional, así como su retribución social, en los diferentes sectores. | F17: 21 | G17: Contar con 70 manuales de prácticas apegados a los indicadores del Sistema para Evaluar la Calidad de Medios Educativos anualmente | H17: ACT-PRDI-NS-2792 | I17: Contribuir desde la Facultad de Ingeniería al cumplimiento de la meta PRDI “Contar con 70 manuales de prácticas apegados a los indicadores del Sistema para Evaluar la Calidad de Medios Educativos anualmente”, con valores absolutos programados de 2027: 2, 2028: 2, 2029: 2, 2030: 2. | J17: Actividad | K17: Sin fórmula | L17: Contar con manuales de prácticas apegados a los indicadores del Sistema para Evaluar la Calidad de Medios Educativos | N17: 2 | O17: 2 | P17: 2 | Q17: 2 | R17: =IF(M17="","",M17) | S17: =IF(N17="","",N17) -> 2 | T17: =IF(O17="","",O17) -> 2 | U17: =IF(P17="","",P17) -> 2 | V17: =IF(Q17="","",Q17) -> 2 | W17: Anual | X17: Subdirección Académica y coordinaciones de licenciatura
A18: 12 | B18: PRDI25-29-Obj-36 | C18: Formar estudiantes de excelencia, a través de estudios profesionales pertinentes e inclusivos, con una vinculación permanente con estudiantes y personas egresadas, para su pleno desarrollo profesional y su contribución al bienestar social. | D18: PRDI25-29-Obj-81 | E18: Fortalecer la formación disciplinar e integral del estudiantado y su educación continua, en congruencia con el modelo educativo institucional, para fomentar su desarrollo humano completo y maximizar su potencial académico y profesional, así como su retribución social, en los diferentes sectores. | F18: 29 | G18: Lograr que 80.03% de las GEI disponibles en SEDUCA sean utilizadas, para 2029 | H18: IND-PRDI-357 | I18: Mejorar o mantener de forma conservadora en la Facultad de Ingeniería el indicador IND-PRDI-357, con la trayectoria 2027: 80%, 2028: 80%, 2029: 80%, 2030: 80%, sustentada en referencia PRDI; no existe serie histórica directamente comparable para la variable. | J18: Indicador | K18: (Número de guías de estudio independiente utilizadas / Número total de guías de estudio independiente vigentes disponibles en SEDUCA) *100 | L18: Número de guías de estudio independiente utilizadas | N18: 8 | O18: 8 | P18: 8 | Q18: 8 | R18: =IF(M19,M18/M19*100,"") | S18: =IF(N19,N18/N19*100,"") -> 80 | T18: =IF(O19,O18/O19*100,"") -> 80 | U18: =IF(P19,P18/P19*100,"") -> 80 | V18: =IF(Q19,Q18/Q19*100,"") -> 80 | W18: Anual | X18: Subdirección Académica y coordinaciones de licenciatura
L19: Número total de guías de estudio independiente vigentes disponibles en SEDUCA | N19: 10 | O19: 10 | P19: 10 | Q19: 10
A20: 13 | B20: PRDI25-29-Obj-36 | C20: Formar estudiantes de excelencia, a través de estudios profesionales pertinentes e inclusivos, con una vinculación permanente con estudiantes y personas egresadas, para su pleno desarrollo profesional y su contribución al bienestar social. | D20: PRDI25-29-Obj-81 | E20: Fortalecer la formación disciplinar e integral del estudiantado y su educación continua, en congruencia con el modelo educativo institucional, para fomentar su desarrollo humano completo y maximizar su potencial académico y profesional, así como su retribución social, en los diferentes sectores. | F20: 30 | G20: Incrementar a 52 000 el número de estudiantes de estudios profesionales en la renovada plataforma seduca, para 2029 | H20: ACT-PRDI-NS-2728 | I20: Contribuir desde la Facultad de Ingeniería al cumplimiento de la meta PRDI “Incrementar a 52 000 el número de estudiantes de estudios profesionales en la renovada plataforma seduca, para 2029”, con valores absolutos programados de 2027: 473, 2028: 710, 2029: 946, 2030: 946. | J20: Actividad | K20: Sin fórmula | L20: Incrementar el número de estudiantes de estudios profesionales en la renovada plataforma seduca | N20: 473 | O20: 710 | P20: 946 | Q20: 946 | R20: =IF(M20="","",M20) | S20: =IF(N20="","",N20) -> 473 | T20: =IF(O20="","",O20) -> 710 | U20: =IF(P20="","",P20) -> 946 | V20: =IF(Q20="","",Q20) -> 946 | W20: Anual | X20: Subdirección Académica y coordinaciones de licenciatura
A21: 14 | B21: PRDI25-29-Obj-36 | C21: Formar estudiantes de excelencia, a través de estudios profesionales pertinentes e inclusivos, con una vinculación permanente con estudiantes y personas egresadas, para su pleno desarrollo profesional y su contribución al bienestar social. | D21: PRDI25-29-Obj-81 | E21: Fortalecer la formación disciplinar e integral del estudiantado y su educación continua, en congruencia con el modelo educativo institucional, para fomentar su desarrollo humano completo y maximizar su potencial académico y profesional, así como su retribución social, en los diferentes sectores. | F21: 33 | G21: Desarrollar 470 actividades académicas de educación continua al año | H21: ACT-PRDI-NS-2805 | I21: Contribuir desde la Facultad de Ingeniería al cumplimiento de la meta PRDI “Desarrollar 470 actividades académicas de educación continua al año”, con valores absolutos programados de 2027: 9, 2028: 9, 2029: 9, 2030: 9. | J21: Actividad | K21: Sin fórmula | L21: Desarrollar actividades académicas de educación continua | N21: 9 | O21: 9 | P21: 9 | Q21: 9 | R21: =IF(M21="","",M21) | S21: =IF(N21="","",N21) -> 9 | T21: =IF(O21="","",O21) -> 9 | U21: =IF(P21="","",P21) -> 9 | V21: =IF(Q21="","",Q21) -> 9 | W21: Anual | X21: Subdirección Académica y coordinaciones de licenciatura
A22: 16 | B22: PRDI25-29-Obj-36 | C22: Formar estudiantes de excelencia, a través de estudios profesionales pertinentes e inclusivos, con una vinculación permanente con estudiantes y personas egresadas, para su pleno desarrollo profesional y su contribución al bienestar social. | D22: PRDI25-29-Obj-81 | E22: Fortalecer la formación disciplinar e integral del estudiantado y su educación continua, en congruencia con el modelo educativo institucional, para fomentar su desarrollo humano completo y maximizar su potencial académico y profesional, así como su retribución social, en los diferentes sectores. | F22: 37 | G22: Certificar en una segunda lengua a 720 estudiantes de estudios profesionales anualmente | H22: ACT-PRDI-NS-2205 | I22: Contribuir desde la Facultad de Ingeniería al cumplimiento de la meta PRDI “Certificar en una segunda lengua a 720 estudiantes de estudios profesionales anualmente”, con valores absolutos programados de 2027: 14, 2028: 14, 2029: 14, 2030: 14. | J22: Actividad | K22: Sin fórmula | L22: Certificar internacionalmente en una segunda lengua a estudiantes de estudios profesionales | N22: 14 | O22: 14 | P22: 14 | Q22: 14 | R22: =IF(M22="","",M22) | S22: =IF(N22="","",N22) -> 14 | T22: =IF(O22="","",O22) -> 14 | U22: =IF(P22="","",P22) -> 14 | V22: =IF(Q22="","",Q22) -> 14 | W22: Anual | X22: Subdirección Académica y coordinaciones de licenciatura
A23: 17 | B23: PRDI25-29-Obj-36 | C23: Formar estudiantes de excelencia, a través de estudios profesionales pertinentes e inclusivos, con una vinculación permanente con estudiantes y personas egresadas, para su pleno desarrollo profesional y su contribución al bienestar social. | D23: PRDI25-29-Obj-82 | E23: Contribuir al acceso, permanencia y egreso del alumnado de estudios profesionales para su formación integral y la conclusión de sus estudios profesionales. | F23: 42 | G23: Incrementar la matrícula a 78 002 estudiantes de estudios profesionales en sus diversas modalidades para 2029 | H23: ACT-PRDI-NS-1764 | I23: Contribuir desde la Facultad de Ingeniería al cumplimiento de la meta PRDI “Incrementar la matrícula a 78 002 estudiantes de estudios profesionales en sus diversas modalidades para 2029”, con valores absolutos programados de 2027: 3004, 2028: 3019, 2029: 3034, 2030: 3049. Sustento en la Matriz de consistencia: «Realizar 1 reunión y 1 encuesta a estudiantes de cada licenciatura cada año de 2028 a 2030 y documentar los ajustes derivados.» | J23: Actividad | K23: Sin fórmula | L23: Atender la matrícula de Estudios Profesionales en sus diversas modalidades | M23: =M14 -> 0 | N23: 3004 | O23: 3019 | P23: 3034 | Q23: 3049 | R23: =IF(M23="","",M23) -> 0 | S23: =IF(N23="","",N23) -> 3004 | T23: =IF(O23="","",O23) -> 3019 | U23: =IF(P23="","",P23) -> 3034 | V23: =IF(Q23="","",Q23) -> 3049 | W23: Anual | X23: Subdirección Académica y coordinaciones de licenciatura
A24: 18 | B24: PRDI25-29-Obj-36 | C24: Formar estudiantes de excelencia, a través de estudios profesionales pertinentes e inclusivos, con una vinculación permanente con estudiantes y personas egresadas, para su pleno desarrollo profesional y su contribución al bienestar social. | D24: PRDI25-29-Obj-82 | E24: Contribuir al acceso, permanencia y egreso del alumnado de estudios profesionales para su formación integral y la conclusión de sus estudios profesionales. | F24: 43 | G24: Contar con una titulación por cohorte a 2029 de 30.5% | H24: IND-PRDI-40 | I24: Mejorar o mantener de forma conservadora en la Facultad de Ingeniería el indicador IND-PRDI-40, con la trayectoria 2027: 3%, 2028: 4%, 2029: 4.95%, 2030: 5.88%, sustentada en serie histórica directamente comparable del sitio. | J24: Indicador | K24: (Titulados al primer año de egreso/Nuevo ingreso n-5 )*100 | L24: Titulados al primer año de egreso | N24: 3 | O24: 4 | P24: 5 | Q24: 6 | R24: =IF(M25,M24/M25*100,"") | S24: =IF(N25,N24/N25*100,"") -> 3 | T24: =IF(O25,O24/O25*100,"") -> 4 | U24: =IF(P25,P24/P25*100,"") -> 4.950495 | V24: =IF(Q25,Q24/Q25*100,"") -> 5.8823529 | W24: Anual | X24: Subdirección Académica y coordinaciones de licenciatura
L25: Nuevo ingreso n-5 | N25: 100 | O25: 100 | P25: 101 | Q25: 102
A26: 19 | B26: PRDI25-29-Obj-36 | C26: Formar estudiantes de excelencia, a través de estudios profesionales pertinentes e inclusivos, con una vinculación permanente con estudiantes y personas egresadas, para su pleno desarrollo profesional y su contribución al bienestar social. | D26: PRDI25-29-Obj-82 | E26: Contribuir al acceso, permanencia y egreso del alumnado de estudios profesionales para su formación integral y la conclusión de sus estudios profesionales. | F26: 44 | G26: Implementar semestralmente 1 programa de fomento a la titulación | H26: ACT-PRDI-NS-2814 | I26: Contribuir desde la Facultad de Ingeniería al cumplimiento de la meta PRDI “Implementar semestralmente 1 programa de fomento a la titulación”, con valores absolutos programados de 2027: 0, 2028: 0, 2029: 2, 2030: 0. | J26: Actividad | K26: Sin fórmula | L26: Implementar un programa de fomento a la titulación | N26: 0 | O26: 0 | P26: 2 | Q26: 0 | R26: =IF(M26="","",M26) | S26: =IF(N26="","",N26) -> 0 | T26: =IF(O26="","",O26) -> 0 | U26: =IF(P26="","",P26) -> 2 | V26: =IF(Q26="","",Q26) -> 0 | W26: Anual | X26: Subdirección Académica y coordinaciones de licenciatura
A27: 20 | B27: PRDI25-29-Obj-36 | C27: Formar estudiantes de excelencia, a través de estudios profesionales pertinentes e inclusivos, con una vinculación permanente con estudiantes y personas egresadas, para su pleno desarrollo profesional y su contribución al bienestar social. | D27: PRDI25-29-Obj-82 | E27: Contribuir al acceso, permanencia y egreso del alumnado de estudios profesionales para su formación integral y la conclusión de sus estudios profesionales. | F27: 45 | G27: Lograr la eficiencia terminal por cohorte en estudios Profesionales de 53.59% en 2029 | H27: IND-NS-127 | I27: Mejorar o mantener de forma conservadora en la Facultad de Ingeniería el indicador IND-NS-127, con la trayectoria 2027: 5.19%, 2028: 6.19%, 2029: 7.19%, 2030: 8.21%, sustentada en serie histórica directamente comparable del sitio. | J27: Indicador | K27: (La suma acumulada del número de egresados de la cohorte de estudios profesionales en cada uno de los años que dura la cohorte/Número total de alumnos de ingreso a primer año de la cohorte)*100 | L27: La suma acumulada del número de egresados de la cohorte de estudios profesionales en cada uno de los años que dura la cohorte | N27: 155 | O27: 186 | P27: 217 | Q27: 249 | R27: =IF(M28,M27/M28*100,"") | S27: =IF(N28,N27/N28*100,"") -> 5.1856808 | T27: =IF(O28,O27/O28*100,"") -> 6.1917443 | U27: =IF(P28,P27/P28*100,"") -> 7.1878105 | V27: =IF(Q28,Q27/Q28*100,"") -> 8.2069875 | W27: Anual | X27: Subdirección Académica y coordinaciones de licenciatura
L28: Número total de alumnos de ingreso a primer año de la cohorte | N28: 2989 | O28: 3004 | P28: 3019 | Q28: 3034
A29: 21 | B29: PRDI25-29-Obj-36 | C29: Formar estudiantes de excelencia, a través de estudios profesionales pertinentes e inclusivos, con una vinculación permanente con estudiantes y personas egresadas, para su pleno desarrollo profesional y su contribución al bienestar social. | D29: PRDI25-29-Obj-82 | E29: Contribuir al acceso, permanencia y egreso del alumnado de estudios profesionales para su formación integral y la conclusión de sus estudios profesionales. | F29: 46 | G29: Disminuir a 7.80% el abandono escolar de estudios profesionales al término de la administración | H29: IND-PRDI-34 | I29: Mejorar o mantener de forma conservadora en la Facultad de Ingeniería el indicador IND-PRDI-34, con la trayectoria 2027: 8.03%, 2028: 7.96%, 2029: 7.88%, 2030: 7.81%, sustentada en serie histórica directamente comparable del sitio. | J29: Indicador | K29: (1-((Matrícula total n mas 1-Nuevo ingreso 1o n mas 1+Egresados n)/(Matrícula total n)))*100 | L29: Matrícula total n mas 1 | M29: =M14 -> 0 | N29: 3004 | O29: 3019 | P29: 3034 | Q29: 3049 | R29: =IF(M32,(1-((M29-M30+M31)/M32))*100,"") | S29: =IF(N32,(1-((N29-N30+N31)/N32))*100,"") -> 8.0294413 | T29: =IF(O32,(1-((O29-O30+O31)/O32))*100,"") -> 7.9560586 | U29: =IF(P32,(1-((P29-P30+P31)/P32))*100,"") -> 7.8834051 | V29: =IF(Q32,(1-((Q29-Q30+Q31)/Q32))*100,"") -> 7.81147 | W29: Anual | X29: Subdirección Académica y coordinaciones de licenciatura
L30: Nuevo ingreso 1o n mas 1 | N30: 722 | O30: 726 | P30: 729 | Q30: 733
L31: Egresados n | N31: 467 | O31: 472 | P31: 476 | Q31: 481
L32: Matrícula total n | N32: 2989 | O32: 3004 | P32: 3019 | Q32: 3034
A33: 22 | B33: PRDI25-29-Obj-36 | C33: Formar estudiantes de excelencia, a través de estudios profesionales pertinentes e inclusivos, con una vinculación permanente con estudiantes y personas egresadas, para su pleno desarrollo profesional y su contribución al bienestar social. | D33: PRDI25-29-Obj-82 | E33: Contribuir al acceso, permanencia y egreso del alumnado de estudios profesionales para su formación integral y la conclusión de sus estudios profesionales. | F33: 53 | G33: Otorgar anualmente 38 000 becas, apoyos o estímulos institucionales a estudiantes de Estudios Profesionales | H33: ACT-PRDI-NS-2297 | I33: Contribuir desde la Facultad de Ingeniería al cumplimiento de la meta PRDI “Otorgar anualmente 38 000 becas, apoyos o estímulos institucionales a estudiantes de Estudios Profesionales”, con valores absolutos programados de 2027: 691, 2028: 691, 2029: 691, 2030: 691. | J33: Actividad | K33: Sin fórmula | L33: Otorgar becas, apoyos o estímulos a alumnos de estudios profesionales para la permanencia y conclusión de estudios | N33: 691 | O33: 691 | P33: 691 | Q33: 691 | R33: =IF(M33="","",M33) | S33: =IF(N33="","",N33) -> 691 | T33: =IF(O33="","",O33) -> 691 | U33: =IF(P33="","",P33) -> 691 | V33: =IF(Q33="","",Q33) -> 691 | W33: Anual | X33: Subdirección Académica y coordinaciones de licenciatura
A34: 23 | B34: PRDI25-29-Obj-36 | C34: Formar estudiantes de excelencia, a través de estudios profesionales pertinentes e inclusivos, con una vinculación permanente con estudiantes y personas egresadas, para su pleno desarrollo profesional y su contribución al bienestar social. | D34: PRDI25-29-Obj-82 | E34: Contribuir al acceso, permanencia y egreso del alumnado de estudios profesionales para su formación integral y la conclusión de sus estudios profesionales. | F34: 55 | G34: Lograr que 98% del total de estudiantes activos de Estudios Profesionales cuenten con servicios de salud a 2029 | H34: IND-PRDI-366 | I34: Mejorar o mantener de forma conservadora en la Facultad de Ingeniería el indicador IND-PRDI-366, con la trayectoria 2027: 94.01%, 2028: 95.34%, 2029: 96.65%, 2030: 97.99%, sustentada en referencia PRDI; no existe serie histórica directamente comparable para la variable. | J34: Indicador | K34: (Alumnos afiliados al Seguro Facultativo de Estudios Profesionales / Matrícula activa de Estudios Profesionales)*100 | L34: Alumnos afiliados al Seguro Facultativo de Estudios Profesionales | N34: 2810 | O34: 2864 | P34: 2918 | Q34: 2973 | R34: =IF(M35,M34/M35*100,"") | S34: =IF(N35,N34/N35*100,"") -> 94.011375 | T34: =IF(O35,O34/O35*100,"") -> 95.339547 | U34: =IF(P35,P34/P35*100,"") -> 96.654521 | V34: =IF(Q35,Q34/Q35*100,"") -> 97.989453 | W34: Anual | X34: Subdirección Académica y coordinaciones de licenciatura
L35: Matrícula activa de Estudios Profesionales | M35: =M14 -> 0 | N35: 2989 | O35: 3004 | P35: 3019 | Q35: 3034
A36: 24 | B36: PRDI25-29-Obj-36 | C36: Formar estudiantes de excelencia, a través de estudios profesionales pertinentes e inclusivos, con una vinculación permanente con estudiantes y personas egresadas, para su pleno desarrollo profesional y su contribución al bienestar social. | D36: PRDI25-29-Obj-82 | E36: Contribuir al acceso, permanencia y egreso del alumnado de estudios profesionales para su formación integral y la conclusión de sus estudios profesionales. | F36: 57 | G36: Lograr la participación de 32 300 estudiantes y personas egresadas en los sectores gubernamental, productivo y social, mediante las prácticas o estancias profesionales, al cierre de la administración | H36: ACT-PRDI-NS-2285 | I36: Contribuir desde la Facultad de Ingeniería al cumplimiento de la meta PRDI “Lograr la participación de 32 300 estudiantes y personas egresadas en los sectores gubernamental, productivo y social, mediante las prácticas o estancias profesionales, al cierre de la administración”, con valores absolutos programados de 2027: 0, 2028: 0, 2029: 588, 2030: 0. | J36: Actividad | K36: Sin fórmula | L36: Lograr la participación de alumnos en los sectores gubernamental, productivo y social mediante las prácticas o estancias profesionales | N36: 0 | O36: 0 | P36: 588 | Q36: 0 | R36: =IF(M36="","",M36) | S36: =IF(N36="","",N36) -> 0 | T36: =IF(O36="","",O36) -> 0 | U36: =IF(P36="","",P36) -> 588 | V36: =IF(Q36="","",Q36) -> 0 | W36: Anual | X36: Subdirección Académica y coordinaciones de licenciatura
A37: 25 | B37: PRDI25-29-Obj-36 | C37: Formar estudiantes de excelencia, a través de estudios profesionales pertinentes e inclusivos, con una vinculación permanente con estudiantes y personas egresadas, para su pleno desarrollo profesional y su contribución al bienestar social. | D37: PRDI25-29-Obj-82 | E37: Contribuir al acceso, permanencia y egreso del alumnado de estudios profesionales para su formación integral y la conclusión de sus estudios profesionales. | F37: 58 | G37: Lograr la participación de 500 estudiantes de estudios profesionales en cursos, talleres o actividades de capacitación de empleabilidad, realizadas en conjunto con instituciones externas, anualmente | H37: ACT-PRDI-NS-2826 | I37: Contribuir desde la Facultad de Ingeniería al cumplimiento de la meta PRDI “Lograr la participación de 500 estudiantes de estudios profesionales en cursos, talleres o actividades de capacitación de empleabilidad, realizadas en conjunto con instituciones externas, anualmente”, con valores absolutos programados de 2027: 10, 2028: 10, 2029: 10, 2030: 10. | J37: Actividad | K37: Sin fórmula | L37: Lograr la participación de estudiantes de estudios profesionales en cursos, talleres o actividades de capacitación de empleabilidad, realizadas en conjunto con instituciones externas | N37: 10 | O37: 10 | P37: 10 | Q37: 10 | R37: =IF(M37="","",M37) | S37: =IF(N37="","",N37) -> 10 | T37: =IF(O37="","",O37) -> 10 | U37: =IF(P37="","",P37) -> 10 | V37: =IF(Q37="","",Q37) -> 10 | W37: Anual | X37: Subdirección Académica y coordinaciones de licenciatura
A38: 26 | B38: PRDI25-29-Obj-36 | C38: Formar estudiantes de excelencia, a través de estudios profesionales pertinentes e inclusivos, con una vinculación permanente con estudiantes y personas egresadas, para su pleno desarrollo profesional y su contribución al bienestar social. | D38: PRDI25-29-Obj-82 | E38: Contribuir al acceso, permanencia y egreso del alumnado de estudios profesionales para su formación integral y la conclusión de sus estudios profesionales. | F38: 61 | G38: Realizar 10 eventos de promoción y difusión en apoyo al desarrollo profesional para el empleo y la inserción laboral, durante la administración | H38: ACT-PRDI-NS-2825 | I38: Contribuir desde la Facultad de Ingeniería al cumplimiento de la meta PRDI “Realizar 10 eventos de promoción y difusión en apoyo al desarrollo profesional para el empleo y la inserción laboral, durante la administración”, con valores absolutos programados de 2027: 1, 2028: 0, 2029: 0, 2030: 0. Sustento en la Matriz de consistencia: «Realizar 1 revisión documentada de las trayectorias y asignaturas con mayor rezago en 2027 y actualizarla una vez al año de 2028 a 2030.» | J38: Actividad | K38: Sin fórmula | L38: Realizar eventos de promoción y difusión en apoyo al desarrollo profesional para el empleo y la inserción laboral | N38: 1 | O38: 0 | P38: 0 | Q38: 0 | R38: =IF(M38="","",M38) | S38: =IF(N38="","",N38) -> 1 | T38: =IF(O38="","",O38) -> 0 | U38: =IF(P38="","",P38) -> 0 | V38: =IF(Q38="","",Q38) -> 0 | W38: Anual | X38: Subdirección Académica y coordinaciones de licenciatura
A39: 27 | B39: PRDI25-29-Obj-36 | C39: Formar estudiantes de excelencia, a través de estudios profesionales pertinentes e inclusivos, con una vinculación permanente con estudiantes y personas egresadas, para su pleno desarrollo profesional y su contribución al bienestar social. | D39: PRDI25-29-Obj-83 | E39: Fortalecer la vinculación, acompañamiento y seguimiento de egresados de estudios profesionales, para favorecer las prácticas profesionales, empleabilidad y colaboración con el sector productivo, con un sentido de identidad. | F39: 64 | G39: Realizar 40 intervenciones de impacto anuales en espacios académicos para fortalecer la vinculación colaborativa entre egresados y estudiantes | H39: ACT-PRDI-NS-2753 | I39: Contribuir desde la Facultad de Ingeniería al cumplimiento de la meta PRDI “Realizar 40 intervenciones de impacto anuales en espacios académicos para fortalecer la vinculación colaborativa entre egresados y estudiantes”, con valores absolutos programados de 2027: 1, 2028: 1, 2029: 1, 2030: 1. Sustento en la Matriz de consistencia: «Validar y documentar el valor de Ref. 2026 durante 2027 y, una vez confirmado, mantenerlo o mejorarlo hasta 2030.» | J39: Actividad | K39: Sin fórmula | L39: Realizar intervenciones de impacto en espacios académicos para fortalecer la vinculación colaborativa entre egresados y estudiantes | N39: 1 | O39: 1 | P39: 1 | Q39: 1 | R39: =IF(M39="","",M39) | S39: =IF(N39="","",N39) -> 1 | T39: =IF(O39="","",O39) -> 1 | U39: =IF(P39="","",P39) -> 1 | V39: =IF(Q39="","",Q39) -> 1 | W39: Anual | X39: Subdirección Académica y coordinaciones de licenciatura

Sheet Hoja1
A1: Proyecto | B1: Actividades | C1: Indicadores | D1: Total
A2: 2 EstudiantadoEstProf | B2: 18 | C2: 9 | D2: =B2+C2 -> 27
A3: 3 Est avanzados excelencia | B3: 6 | C3: 1 | D3: =B3+C3 -> 7
A4: 4 Investigación abierta | B4: 3 | C4: 5 | D4: =B4+C4 -> 8
A5: 5 Innovación, desarrollo tec | B5: 2 | C5: 0 | D5: =B5+C5 -> 2
A6: 6 Dif y divulga de la ciencia | B6: 4 | C6: 0 | D6: =B6+C6 -> 4
A7: 7 Cultura desarrollo integral | B7: 6 | C7: 0 | D7: =B7+C7 -> 6
A8: 8 Deporte universitario | B8: 2 | C8: 3 | D8: =B8+C8 -> 5
A9: 9 Fortalecimiento docente | B9: 4 | C9: 6 | D9: =B9+C9 -> 10
A10: 10 Dignificación las y los trab | B10: 0 | C10: 3 | D10: =B10+C10 -> 3
A11: 11 Gestión administrativa | B11: 2 | C11: 0 | D11: =B11+C11 -> 2
A12: 12 Fortalecimiento tecnológico | B12: 2 | C12: 0 | D12: =B12+C12 -> 2
A13: 13 Gobernanza | B13: 8 | C13: 0 | D13: =B13+C13 -> 8
... A19: 22 Sostenibilidad ambiental | B19: 12 | C19: 0 | D19: =B19+C19 -> 12
B20: =SUM(B2:B19) -> 91 | C20: =SUM(C2:C19) -> 32 | D20: =SUM(D2:D19) -> 123

Sheet 3 Est avanzados excelencia
A1: N.P. | B1: Clave Objetivo General | C1: Objetivo General | D1: Clave Objetivo Específico | E1: Objetivo Específico | F1: No. de meta en el PRDI | G1: Meta PRDI | H1: Clave de la meta | I1: Meta del espacio académico | J1: Actividad/Indicador | K1: Método de cálculo | L1: Nombre de las variables | M1: Valor de las variables | R1: Valor de los indicadores | W1: Medición (anual o acumulada) | X1: Área responsable
M2: Ref. 2026 | N2: 2027 | O2: 2028 | P2: 2029 | Q2: 2030 | R2: Ref. 2026 | S2: 2027 | T2: 2028 | U2: 2029 | V2: 2030
A3: 1 | B3: PRDI25-29-Obj-37 | C3: Garantizar una formación en estudios avanzados de excelencia y pertinencia social, a través del desarrollo de programas innovadores con la integración de la investigación de la Agenda Estratégica de Investigación, para asegurar que el conocimiento generado impulse la transformación social. | D3: PRDI2025-2029-Obj-59 | E3: Incrementar la matrícula de estudios avanzados con enfoque de equidad e inclusión regional para diversificar el acceso a la formación de alto nivel. | F3: 6 | G3: Contar con 233 estudiantes de estudios avanzados participantes en estancias cortas o movilidad académica, a 2029 | H3: ACT-PRDI-NS-2838 | I3: Contribuir desde la Facultad de Ingeniería al cumplimiento de la meta PRDI “Contar con 233 estudiantes de estudios avanzados participantes en estancias cortas o movilidad académica, a 2029”, con valores absolutos programados de 2027: 3, 2028: 4, 2029: 5, 2030: 5. Sustento en la Matriz de consistencia: «Realizar 1 reunión y 1 encuesta a estudiantes y profesorado de posgrado cada año de 2028 a 2030 y documentar los ajustes derivados.» | J3: Actividad | K3: Sin fórmula | L3: Contar con estudiantes de estudios avanzados participantes en estancias cortas o movilidad académica | N3: 3 | O3: 4 | P3: 5 | Q3: 5 | R3: =IF(M3="","",M3) | S3: =IF(N3="","",N3) -> 3 | T3: =IF(O3="","",O3) -> 4 | U3: =IF(P3="","",P3) -> 5 | V3: =IF(Q3="","",Q3) -> 5 | W3: Anual | X3: Coordinación de Estudios Avanzados
A4: 2 | B4: PRDI25-29-Obj-37 | C4: Garantizar una formación en estudios avanzados de excelencia y pertinencia social, a través del desarrollo de programas innovadores con la integración de la investigación de la Agenda Estratégica de Investigación, para asegurar que el conocimiento generado impulse la transformación social. | D4: PRDI2025-2029-Obj-59 | E4: Incrementar la matrícula de estudios avanzados con enfoque de equidad e inclusión regional para diversificar el acceso a la formación de alto nivel. | F4: 16 | G4: Contar 4 350 alumnos en estudios avanzados, a 2029 | H4: ACT-PRDI-NS-2685 | I4: Contribuir desde la Facultad de Ingeniería al cumplimiento de la meta PRDI “Contar 4 350 alumnos en estudios avanzados, a 2029”, con valores absolutos programados de 2027: 40, 2028: 60, 2029: 80, 2030: 80. | J4: Actividad | K4: Sin fórmula | L4: Atender la matrícula de estudios avanzados para la generación y aplicación del conocimiento | N4: 40 | O4: 60 | P4: 80 | Q4: 80 | R4: =IF(M4="","",M4) | S4: =IF(N4="","",N4) -> 40 | T4: =IF(O4="","",O4) -> 60 | U4: =IF(P4="","",P4) -> 80 | V4: =IF(Q4="","",Q4) -> 80 | W4: Anual | X4: Coordinación de Estudios Avanzados
A5: 3 | B5: PRDI25-29-Obj-37 | C5: Garantizar una formación en estudios avanzados de excelencia y pertinencia social, a través del desarrollo de programas innovadores con la integración de la investigación de la Agenda Estratégica de Investigación, para asegurar que el conocimiento generado impulse la transformación social. | D5: PRDI25-29-Obj-84 | E5: Consolidar una oferta educativa de estudios avanzados de excelencia, para garantizar la inclusión, la pertinencia social y la alineación con las demandas de los sectores productivo, gubernamental y social. | F5: 12 | G5: Ofertar 1 nuevo programa de estudios avanzados o diplomado superior en los CU y UAP vinculado con entidades de gobierno o industria, anualmente | H5: ACT-PRDI-NS-2844 | I5: Contribuir desde la Facultad de Ingeniería al cumplimiento de la meta PRDI “Ofertar 1 nuevo programa de estudios avanzados o diplomado superior en los CU y UAP vinculado con entidades de gobierno o industria, anualmente”, con valores absolutos programados de 2027: 1, 2028: 1, 2029: 1, 2030: 1. | J5: Actividad | K5: Sin fórmula | L5: Ofertar nuevos programas de estudios avanzados o diplomado superior en los CU y UAP vinculado con entidades de gobierno o industria | N5: 1 | O5: 1 | P5: 1 | Q5: 1 | R5: =IF(M5="","",M5) | S5: =IF(N5="","",N5) -> 1 | T5: =IF(O5="","",O5) -> 1 | U5: =IF(P5="","",P5) -> 1 | V5: =IF(Q5="","",Q5) -> 1 | W5: Anual | X5: Coordinación de Estudios Avanzados
A6: 4 | B6: PRDI25-29-Obj-37 | C6: Garantizar una formación en estudios avanzados de excelencia y pertinencia social, a través del desarrollo de programas innovadores con la integración de la investigación de la Agenda Estratégica de Investigación, para asegurar que el conocimiento generado impulse la transformación social. | D6: PRDI25-29-Obj-84 | E6: Consolidar una oferta educativa de estudios avanzados de excelencia, para garantizar la inclusión, la pertinencia social y la alineación con las demandas de los sectores productivo, gubernamental y social. | F6: 15 | G6: Registrar 50 protocolos de investigación de alumnos de estudios avanzados con temáticas vinculadas a la Agenda Estratégica de Investigación, anualmente | H6: ACT-PRDI-NS-2847 | I6: Contribuir desde la Facultad de Ingeniería al cumplimiento de la meta PRDI “Registrar 50 protocolos de investigación de alumnos de estudios avanzados con temáticas vinculadas a la Agenda Estratégica de Investigación, anualmente”, con valores absolutos programados de 2027: 1, 2028: 1, 2029: 1, 2030: 1. | J6: Actividad | K6: Sin fórmula | L6: Registrar protocolos de investigación de alumnos de estudios avanzados con temáticas vinculadas a la Agenda Estratégica de Investigación | N6: 1 | O6: 1 | P6: 1 | Q6: 1 | R6: =IF(M6="","",M6) | S6: =IF(N6="","",N6) -> 1 | T6: =IF(O6="","",O6) -> 1 | U6: =IF(P6="","",P6) -> 1 | V6: =IF(Q6="","",Q6) -> 1 | W6: Anual | X6: Coordinación de Estudios Avanzados
A7: 5 | B7: PRDI25-29-Obj-37 | C7: Garantizar una formación en estudios avanzados de excelencia y pertinencia social, a través del desarrollo de programas innovadores con la integración de la investigación de la Agenda Estratégica de Investigación, para asegurar que el conocimiento generado impulse la transformación social. | D7: PRDI25-29-Obj-84 | E7: Consolidar una oferta educativa de estudios avanzados de excelencia, para garantizar la inclusión, la pertinencia social y la alineación con las demandas de los sectores productivo, gubernamental y social. | F7: 18 | G7: Generar protocolos de acción para incrementar la tasa de graduación y la eficiencia terminal en 10 espacios académicos, en 2026 | H7: ACT-PRDI-NS-2848 | I7: Contribuir desde la Facultad de Ingeniería al cumplimiento de la meta PRDI “Generar protocolos de acción para incrementar la tasa de graduación y la eficiencia terminal en 10 espacios académicos, en 2026”, con valores absolutos programados de 2027: 0, 2028: 0, 2029: 1, 2030: 0. | J7: Actividad | K7: Sin fórmula | L7: Generar protocolos de acción para incrementar la tasa de graduación y la eficiencia terminal en espacios académicos | N7: 0 | O7: 0 | P7: 1 | Q7: 0 | R7: =IF(M7="","",M7) | S7: =IF(N7="","",N7) -> 0 | T7: =IF(O7="","",O7) -> 0 | U7: =IF(P7="","",P7) -> 1 | V7: =IF(Q7="","",Q7) -> 0 | W7: Anual | X7: Coordinación de Estudios Avanzados
A8: 6 | B8: PRDI25-29-Obj-37 | C8: Garantizar una formación en estudios avanzados de excelencia y pertinencia social, a través del desarrollo de programas innovadores con la integración de la investigación de la Agenda Estratégica de Investigación, para asegurar que el conocimiento generado impulse la transformación social. | D8: PRDI25-29-Obj-84 | E8: Consolidar una oferta educativa de estudios avanzados de excelencia, para garantizar la inclusión, la pertinencia social y la alineación con las demandas de los sectores productivo, gubernamental y social. | F8: 19 | G8: Incrementar a 1190 graduados de estudios avanzados, a 2029 | H8: ACT-PRDI-NS-2849 | I8: Contribuir desde la Facultad de Ingeniería al cumplimiento de la meta PRDI “Incrementar a 1190 graduados de estudios avanzados, a 2029”, con valores absolutos programados de 2027: 11, 2028: 17, 2029: 22, 2030: 22. Sustento en la Matriz de consistencia: «Realizar 1 revisión documentada de el ingreso, la permanencia y el egreso por posgrado en 2027 y actualizarla una vez al año de 2028 a 2030.» | J8: Actividad | K8: Sin fórmula | L8: Incrementar graduados de estudios avanzados | N8: 11 | O8: 17 | P8: 22 | Q8: 22 | R8: =IF(M8="","",M8) | S8: =IF(N8="","",N8) -> 11 | T8: =IF(O8="","",O8) -> 17 | U8: =IF(P8="","",P8) -> 22 | V8: =IF(Q8="","",Q8) -> 22 | W8: Anual | X8: Coordinación de Estudios Avanzados
A9: 7 | B9: PRDI25-29-Obj-37 | C9: Garantizar una formación en estudios avanzados de excelencia y pertinencia social, a través del desarrollo de programas innovadores con la integración de la investigación de la Agenda Estratégica de Investigación, para asegurar que el conocimiento generado impulse la transformación social. | D9: PRDI25-29-Obj-84 | E9: Consolidar una oferta educativa de estudios avanzados de excelencia, para garantizar la inclusión, la pertinencia social y la alineación con las demandas de los sectores productivo, gubernamental y social. | F9: 20 | G9: Incrementar a 17.56% la graduación de estudios avanzados por la opción de trabajo terminal de grado, a 2029 | H9: IND-PRDI-365 | I9: Mejorar o mantener de forma conservadora en la Facultad de Ingeniería el indicador IND-PRDI-365, con la trayectoria 2027: 15.15%, 2028: 18.18%, 2029: 18.18%, 2030: 18.18%, sustentada en referencia PRDI; no existe serie histórica directamente comparable para la variable. Sustento en la Matriz de consistencia: «Validar y documentar el valor de Ref. 2026 durante 2027 y, una vez confirmado, mantenerlo o mejorarlo hasta 2030.» | J9: Indicador | K9: (Número de alumnos graduados por la opción de trabajo terminal de grado en el año que se reporta/Total de alumnos graduados en el año que se reporta)*100 | L9: Número de alumnos graduados por la opción de trabajo terminal de grado en el año que se reporta | N9: 5 | O9: 6 | P9: 6 | Q9: 6 | R9: =IF(M10,M9/M10*100,"") | S9: =IF(N10,N9/N10*100,"") -> 15.151515 | T9: =IF(O10,O9/O10*100,"") -> 18.181818 | U9: =IF(P10,P9/P10*100,"") -> 18.181818 | V9: =IF(Q10,Q9/Q10*100,"") -> 18.181818 | W9: Anual | X9: Coordinación de Estudios Avanzados
L10: Total de alumnos graduados en el año que se reporta)*100 | N10: 33 | O10: 33 | P10: 33 | Q10: 33

Sheet 4 Investigación abierta
A1: N.P. | B1: Clave Objetivo General | C1: Objetivo General | D1: Clave Objetivo Específico | E1: Objetivo Específico | F1: No. de meta en el PRDI | G1: Meta PRDI | H1: Clave de la meta | I1: Meta del espacio académico | J1: Actividad/Indicador | K1: Método de cálculo | L1: Nombre de las variables | M1: Valor de las variables | R1: Valor de los indicadores | W1: Medición (anual o acumulada) | X1: Área responsable
M2: Ref. 2026 | N2: 2027 | O2: 2028 | P2: 2029 | Q2: 2030 | R2: Ref. 2026 | S2: 2027 | T2: 2028 | U2: 2029 | V2: 2030
A3: 1 | B3: PRDI25-29-Obj-38 | C3: Impulsar la investigación científica, humanística, tecnológica y de innovación priorizando la calidad, inclusión, equidad, retribución social y multilingüismo, a través del apoyo a proyectos sólidos, el fortalecimiento de redes en la comunidad investigadora y la optimización de recursos e infraestructura, en el marco del nuevo Modelo de Ciencia Abierta para la Transformación Social | D3: PRDI2025-2029-Obj-60 | E3: Fomentar la investigación abierta, equitativa y de calidad, así como transparentar su dimensión de retribución social, incentivar el diálogo de saberes y la participación activa de la comunidad universitaria de forma incluyente. | F3: 19 | G3: Contar con 200 CA de calidad, a 2028 | H3: ACT-PRDI-NS-2870 | I3: Contribuir desde la Facultad de Ingeniería al cumplimiento de la meta PRDI “Contar con 200 CA de calidad, a 2028”, con valores absolutos programados de 2027: 3, 2028: 3, 2029: 3, 2030: 3. Sustento en la Matriz de consistencia: «Mantener al menos 3 cuerpos académicos de calidad en cada medición anual de 2027 a 2030.» | J3: Actividad | K3: Sin fórmula | L3: Contar con Cuerpos Académicos de calidad | M3: 3 | N3: 3 | O3: 3 | P3: 3 | Q3: 3 | R3: =IF(M3="","",M3) -> 3 | S3: =IF(N3="","",N3) -> 3 | T3: =IF(O3="","",O3) -> 3 | U3: =IF(P3="","",P3) -> 3 | V3: =IF(Q3="","",Q3) -> 3 | W3: Anual | X3: Coordinación de Investigación
A4: 2 | B4: PRDI25-29-Obj-38 | C4: Impulsar la investigación científica, humanística, tecnológica y de innovación priorizando la calidad, inclusión, equidad, retribución social y multilingüismo, a través del apoyo a proyectos sólidos, el fortalecimiento de redes en la comunidad investigadora y la optimización de recursos e infraestructura, en el marco del nuevo Modelo de Ciencia Abierta para la Transformación Social | D4: PRDI2025-2029-Obj-60 | E4: Fomentar la investigación abierta, equitativa y de calidad, así como transparentar su dimensión de retribución social, incentivar el diálogo de saberes y la participación activa de la comunidad universitaria de forma incluyente. | F4: 20 | G4: Mantener 98.68% de los CA que realizan investigación que contribuye a la solución de problemas sociales, a 2029 | H4: IND-PRDI-221 | I4: Mejorar o mantener de forma conservadora en la Facultad de Ingeniería el indicador IND-PRDI-221, con la trayectoria 2027: 100%, 2028: 100%, 2029: 100%, 2030: 100%, sustentada en serie histórica directamente comparable del sitio. | J4: Indicador | K4: (Número de cuerpos académicos registrados en SEP que realizan investigación que contribuyen a la solución de problemas sociales/Total de cuerpos académicos registrados en SEP)*100 | L4: Número de cuerpos académicos registrados en SEP que realizan investigación que contribuyen a la solución de problemas sociales | N4: 3 | O4: 3 | P4: 3 | Q4: 3 | R4: =IF(M5,M4/M5*100,"") | S4: =IF(N5,N4/N5*100,"") -> 100 | T4: =IF(O5,O4/O5*100,"") -> 100 | U4: =IF(P5,P4/P5*100,"") -> 100 | V4: =IF(Q5,Q4/Q5*100,"") -> 100 | W4: Anual | X4: Coordinación de Investigación
L5: Total de cuerpos académicos registrados en SEP | N5: 3 | O5: 3 | P5: 3 | Q5: 3
A6: 3 | B6: PRDI25-29-Obj-38 | C6: Impulsar la investigación científica, humanística, tecnológica y de innovación priorizando la calidad, inclusión, equidad, retribución social y multilingüismo, a través del apoyo a proyectos sólidos, el fortalecimiento de redes en la comunidad investigadora y la optimización de recursos e infraestructura, en el marco del nuevo Modelo de Ciencia Abierta para la Transformación Social | D6: PRDI2025-2029-Obj-60 | E6: Fomentar la investigación abierta, equitativa y de calidad, así como transparentar su dimensión de retribución social, incentivar el diálogo de saberes y la participación activa de la comunidad universitaria de forma incluyente. | F6: 21 | G6: Mantener el 49.59% de los PTC con participación en redes con pares extranjeros, anualmente | H6: IND-PRDI-368 | I6: Mejorar o mantener de forma conservadora en la Facultad de Ingeniería el indicador IND-PRDI-368, con la trayectoria 2027: 47.14%, 2028: 48.57%, 2029: 49.3%, 2030: 49.3%, sustentada en referencia PRDI; no existe serie histórica directamente comparable para la variable. | J6: Indicador | K6: (Número de Profesores de Tiempo Completo con participación en redes con pares extranjeros/Total de Profesores de Tiempo Completo)*100 | L6: Número de Profesores de Tiempo Completo con participación en redes con pares extranjeros | N6: 33 | O6: 34 | P6: 35 | Q6: 35 | R6: =IF(M7,M6/M7*100,"") | S6: =IF(N7,N6/N7*100,"") -> 47.142857 | T6: =IF(O7,O6/O7*100,"") -> 48.571429 | U6: =IF(P7,P6/P7*100,"") -> 49.295775 | V6: =IF(Q7,Q6/Q7*100,"") -> 49.295775 | W6: Anual | X6: Coordinación de Investigación
L7: Total de Profesores de Tiempo Completo | N7: 70 | O7: 70 | P7: 71 | Q7: 71
A8: 4 | B8: PRDI25-29-Obj-38 | C8: Impulsar la investigación científica, humanística, tecnológica y de innovación priorizando la calidad, inclusión, equidad, retribución social y multilingüismo, a través del apoyo a proyectos sólidos, el fortalecimiento de redes en la comunidad investigadora y la optimización de recursos e infraestructura, en el marco del nuevo Modelo de Ciencia Abierta para la Transformación Social | D8: PRDI2025-2029-Obj-60 | E8: Fomentar la investigación abierta, equitativa y de calidad, así como transparentar su dimensión de retribución social, incentivar el diálogo de saberes y la participación activa de la comunidad universitaria de forma incluyente. | F8: 22 | G8: Mantener 49.81% de los PTC que participan en redes nacionales, anualmente | H8: IND-PRDI-370 | I8: Mejorar o mantener de forma conservadora en la Facultad de Ingeniería el indicador IND-PRDI-370, con la trayectoria 2027: 47.14%, 2028: 48.57%, 2029: 49.3%, 2030: 49.3%, sustentada en referencia PRDI; no existe serie histórica directamente comparable para la variable. | J8: Indicador | K8: (Número de Profesores de Tiempo Completo con participación en redes nacionales/Total de Profesores de Tiempo Completo)*100 | L8: Número de Profesores de Tiempo Completo con participación en redes nacionales | N8: 33 | O8: 34 | P8: 35 | Q8: 35 | R8: =IF(M9,M8/M9*100,"") | S8: =IF(N9,N8/N9*100,"") -> 47.142857 | T8: =IF(O9,O8/O9*100,"") -> 48.571429 | U8: =IF(P9,P8/P9*100,"") -> 49.295775 | V8: =IF(Q9,Q8/Q9*100,"") -> 49.295775 | W8: Anual | X8: Coordinación de Investigación
L9: Total de Profesores de Tiempo Completo | M9: =M7 -> 0 | N9: 70 | O9: 70 | P9: 71 | Q9: 71
